Workbook

Sheet 汇总
C1: 菲律宾 07月01- | S1: 26 | AJ1: 菲律宾 06月01- | AZ1: 30 | BQ1: 菲律宾 05月01- | CI1: 31 | CX1: 菲律宾 04月01- | DP1: 30 | EE1: 菲律宾 03月01- | EW1: 31 | FN1: 菲律宾 02月01 - | GF1: 28 | GU1: 31 | GV1: 菲律宾 01月01 - | HL1: 31 | ID1: 天成 12月01 - | IT1: 31 | JL1: 天成 11月01 - | KB1: 30 | KT1: 天成 10月01 - | LJ1: 31 | MB1: 天成 9月01- | MR1: 30 | NJ1: 天成 8月01- | NZ1: 31 | OS1: 天成 7月01 - 7月 | PF1: 31 | QF1: 天成 6月01 - 6月 | QG1: 30 | QU1: 天成 5月01 - 5月31 | RQ1: 天成 4月1-30 | SM1: 天成 3月1-31 | TH1: 2月1-28 | UD1: 天成 1月1-31 | UZ1: 天成 12月1-31
C2: 平台 | D2: 现场人数 | E2: 转线上人数 | F2: 线上人数 | G2: 人均开发 | H2: 总注册 | I2: 总开发人数 | J2: 首存金额 | K2: 首存总金额 | L2: 首提总金额 | M2: 新客总存 | N2: 新客总提 | O2: 新客存提差 | P2: 一级首存 | Q2: 一级存款 | R2: 一级提款 | S2: 充值人数 | T2: 复存人数 | U2: 存款 | V2: 提款 | W2: 存提差 | X2: 线上员工资 | Y2: 平台盈亏 | Z2: 充值 手续费3.5% | AA2: 平台 服务费20% | AB2: 现场员工资 | AC2: 转线上员工资 | AD2: 净利润 | AE2: 新客单价 | AF2: 客单价 | AG2: 支出回报率 | AH2: 投产比 | AJ2: 平台 | AK2: 现场人数 | AL2: 转线上人数 | AM2: 线上人数 | AN2: 人均开发 | AO2: 总注册 | AP2: 总开发人数 | AQ2: 首存金额 | AR2: 首存总金额 | AS2: 首提总金额 | AT2: 新客总存 | AU2: 新客总提 | AV2: 新客存提差 | AW2: 一级首存 | AX2: 一级存款 | AY2: 一级提款 | AZ2: 充值人数 | BA2: 复存人数 | BB2: 存款 | BC2: 提款 | BD2: 存提差 | BE2: 线上员工资 | BF2: 平台盈亏 | BG2: 充值 手续费3.5% | BH2: 平台 服务费20% | BI2: 现场员工资 | BJ2: 转线上员工资 | BK2: 净利润 | BL2: 新客单价 | BM2: 客单价 | BN2: 支出回报率 | BO2: 投产比 | BQ2: 平台 | BR2: 现场人数 | BS2: 转线上人数 | BT2: 线上人数 | BU2: 人均开发 | BV2: 总注册 | BW2: 总开发人数 | BX2: 首存金额 | BY2: 首存总金额 | BZ2: 首提总金额 | CA2: 新客总存 | CB2: 新客总提 | CC2: 新客存提差 | CD2: 一级首存 | CE2: 一级存款 | CF2: 一级提款 | CG2: 充值人数 | CH2: 复存人数 | CI2: 存款 | CJ2: 提款 | CK2: 存提差 | CL2: 线上员工资 | CM2: 平台盈亏 | CN2: 充值 手续费3.5% | CO2: 平台 服务费20% | CP2: 现场员工资 | CQ2: 转线上员工资 | CR2: 净利润 | CS2: 新客单价 | CT2: 客单价 | CU2: 支出回报率 | CV2: 投产比 | CX2: 平台 | CY2: 现场人数 | CZ2: 转线上人数 | DA2: 线上人数 | DB2: 人均开发 | DC2: 总注册 | DD2: 总开发人数 | DE2: 首存金额 | DF2: 首存总金额 | DG2: 首提总金额 | DH2: 新客总存 | DI2: 新客总提 | DJ2: 新客存提差 | DK2: 一级首存 | DL2: 一级存款 | DM2: 一级提款 | DN2: 充值人数 | DO2: 复存人数 | DP2: 存款 | DQ2: 提款 | DR2: 存提差 | DS2: 线上员工资 | DT2: 平台盈亏 | DU2: 充值 手续费3.5% | DV2: 平台 服务费20% | DW2: 现场员工资 | DX2: 转线上员工资 | DY2: 净利润 | DZ2: 新客单价 | EA2: 客单价 | EB2: 支出回报率 | EC2: 投产比 | EE2: 平台 | EF2: 现场人数 | EG2: 转线上人数 | EH2: 线上人数 | EI2: 人均开发 | EJ2: 总注册 | EK2: 总开发人数 | EL2: 首存金额 | EM2: 首存总金额 | EN2: 首提总金额 | EO2: 新客总存 | EP2: 新客总提 | EQ2: 新客存提差 | ER2: 一级首存 | ES2: 一级存款 | ET2: 一级提款 | EU2: 充值人数 | EV2: 复存人数 | EW2: 存款 | EX2: 提款 | EY2: 存提差 | EZ2: 线上员工资 | FA2: 平台盈亏 | FB2: 充值 手续费3.5% | FC2: 平台 服务费20% | FD2: 现场员工资 | FE2: 转线上员工资 | FF2: 净利润 | FG2: 新客单价 | FH2: 客单价 | FI2: 支出回报率 | FJ2: 投产比 | FN2: 平台 | FO2: 现场人数 | FP2: 转线上人数 | FQ2: 线上人数 | FR2: 人均开发 | FS2: 总注册 | FT2: 总开发人数 | FU2: 首存金额 | FV2: 首存总金额 | FW2: 首提总金额 | FX2: 新客总存 | FY2: 新客总提 | FZ2: 新客存提差 | GA2: 一级首存 | GB2: 一级存款 | GC2: 一级提款 | GD2: 充值人数 | GE2: 复存人数 | GF2: 存款 | GG2: 提款 | GH2: 存提差 | GI2: 线上员工资 | GJ2: 平台盈亏 | GK2: 充值 手续费3.5% | GL2: 平台 服务费20% | GM2: 现场员工资 | GN2: 转线上员工资 | GO2: 净利润 | GP2: 新客单价 | GQ2: 客单价 | GR2: 支出回报率 | GS2: 投产比 | GV2: 平台 | GW2: 现场人数 | GX2: 转线上人数 | GY2: 线上人数 | GZ2: 人均开发 | HA2: 总注册 | HB2: 总开发人数 | HC2: 首存金额 | HD2: 首存总金额 | HE2: 首提总金额 | HF2: 新客总存 | HG2: 新客总提 | HH2: 新客存提差 | HI2: 一级首存 | HJ2: 一级存款 | HK2: 一级提款 | HL2: 充值人数 | HM2: 复存人数 | HN2: 存款 | HO2: 提款 | HP2: 存提差 | HQ2: 线上员工资 | HR2: 平台盈亏 | HS2: 充值 手续费3.5% | HT2: 平台 服务费20% | HU2: 现场员工资 | HV2: 转线上员工资 | HW2: 净利润 | HX2: 新客单价 | HY2: 客单价 | HZ2: 支出回报率 | IA2: 投产比 | ID2: 平台 | IE2: 现场人数 | IF2: 转线上人数 | IG2: 线上人数 | IH2: 人均开发 | II2: 总注册 | IJ2: 总开发人数 | IK2: 首存金额 | IL2: 首存总金额 | IM2: 首提总金额 | IN2: 新客总存 | IO2: 新客总提 | IP2: 新客存提差 | IQ2: 一级首存 | IR2: 一级存款 | IS2: 一级提款 | IT2: 充值人数 | IU2: 复存人数 | IV2: 存款 | IW2: 提款 | IX2: 存提差 | IY2: 线上员工资 | IZ2: 平台盈亏 | JA2: 充值 手续费3.5% | JB2: 平台 服务费20% | JC2: 现场员工资 | JD2: 转线上员工资 | JE2: 净利润 | JF2: 新客单价 | JG2: 客单价 | JH2: 支出回报率 | JI2: 投产比 | JL2: 平台 | JM2: 现场人数 | JN2: 转线上人数 | JO2: 线上人数 | JP2: 人均开发 | JQ2: 总注册 | JR2: 总开发人数 | JS2: 首存金额 | JT2: 首存总金额 | JU2: 首提总金额 | JV2: 新客总存 | JW2: 新客总提 | JX2: 新客存提差 | JY2: 一级首存 | JZ2: 一级存款 | KA2: 一级提款 | KB2: 充值人数 | KC2: 复存人数 | KD2: 存款 | KE2: 提款 | KF2: 存提差 | KG2: 线上员工资 | KH2: 平台盈亏 | KI2: 充值 手续费3.5% | KJ2: 平台 服务费20% | KK2: 现场员工资 | KL2: 转线上员工资 | KM2: 净利润 | KN2: 新客单价 | KO2: 客单价 | KP2: 支出回报率 | KQ2: 投产比 | KT2: 平台 | KU2: 现场人数 | KV2: 转线上人数 | KW2: 线上人数 | KX2: 人均开发 | KY2: 总注册 | KZ2: 总开发人数 | LA2: 首存金额 | LB2: 首存总金额 | LC2: 首提总金额 | LD2: 新客总存 | LE2: 新客总提 | LF2: 新客存提差 | LG2: 一级首存 | LH2: 一级存款 | LI2: 一级提款 | LJ2: 充值人数 | LK2: 复存人数 | LL2: 存款 | LM2: 提款 | LN2: 存提差 | LO2: 线上员工资 | LP2: 平台盈亏 | LQ2: 充值 手续费3.5% | LR2: 平台 服务费20% | LS2: 现场员工资 | LT2: 转线上员工资 | LU2: 净利润 | LV2: 新客单价 | LW2: 客单价 | LX2: 支出回报率 | LY2: 投产比 | MB2: 平台 | MC2: 现场人数 | MD2: 转线上人数 | ME2: 线上人数 | MF2: 人均开发 | MG2: 总注册 | MH2: 总开发人数 | MI2: 首存金额 | MJ2: 首存总金额 | MK2: 首提总金额 | ML2: 新客总存 | MM2: 新客总提 | MN2: 新客存提差 | MO2: 一级首存 | MP2: 一级存款 | MQ2: 一级提款 | MR2: 充值人数 | MS2: 复存人数 | MT2: 存款 | MU2: 提款 | MV2: 存提差 | MW2: 线上员工资 | MX2: 平台盈亏 | MY2: 充值 手续费3.5% | MZ2: 平台 服务费20% | NA2: 现场员工资 | NB2: 转线上员工资 | NC2: 净利润 | ND2: 新客单价 | NE2: 客单价 | NF2: 支出回报率 | NG2: 投产比 | NJ2: 平台 | NK2: 现场人数 | NL2: 转线上人数 | NM2: 线上人数 | NN2: 人均开发 | NO2: 总注册 | NP2: 总开发人数 | NQ2: 首存金额 | NR2: 首存总金额 | NS2: 首提总金额 | NT2: 新客总存 | NU2: 新客总提 | NV2: 新客存提差 | NW2: 一级首存 | NX2: 一级存款 | NY2: 一级提款 | NZ2: 充值人数 | OA2: 复存人数 | OB2: 存款 | OC2: 提款 | OD2: 存提差 | OE2: 线上员工资 | OF2: 平台盈亏 | OG2: 充值 手续费3.5% | OH2: 平台 服务费20% | OI2: 现场员工资 | OJ2: 转线上员工资 | OK2: 净利润 | OL2: 新客单价 | OM2: 客单价 | ON2: 支出回报率 | OO2: 投产比 | OS2: 平台 | OT2: 现场人数 | OU2: 线上人数 | OV2: 总注册 | OW2: 总开发人数 | OX2: 首存金额 | OY2: 首存总金额 | OZ2: 首提总金额 | PA2: 新客总存 | PB2: 新客总提 | PC2: 充值人数 | PD2: 复存人数 | PE2: 存款 | PF2: 提款 | PG2: 存提差 | PH2: 线上员工资 | PI2: 平台盈亏 | PJ2: 充值手续费3.5% | PK2: 平台服务费20% | PL2: 现场员工资 | PM2: 净利润 | PN2: 新客单价 | PO2: 客单价 | PP2: 支出回报率 | PQ2: 投产比 | PU2: 平台 | PV2: 现场人数 | PW2: 线上人数 | PX2: 注册 | PY2: 首存 | PZ2: 首存金额 | QA2: 新客首存总金额 | QB2: 新客首提总金额 | QC2: 充值人数 | QD2: 复存人数 | QE2: 存款 | QF2: 提款 | QG2: 存提差 | QH2: 外部人员工资 | QI2: 平台盈亏 | QJ2: 充值手续费3.5% | QK2: 平台服务费20% | QL2: 现场人员工资 | QM2: 净利润 | QN2: 新款客单价 | QO2: 人均客单价 | QP2: 支出回报率 | QQ2: 投产比 | QU2: 平台 | QV2: 人数 | QW2: 注册 | QX2: 首存 | QY2: 首存/总存金额 | QZ2: 充值人数 | RA2: 存款 | RB2: 提款 | RC2: 提款 | RD2: 存提差 | RE2: 外部人员工资 | RF2: 平台盈亏 | RG2: 充值手续费3.5% | RH2: 平台服务费10% | RI2: 现场人员工资 | RJ2: 净利润 | RK2: 人均客单价 | RL2: 支出回报率 | RM2: 投产比 | RQ2: 平台 | RR2: 人数 | RS2: 注册 | RT2: 首存 | RU2: 首存/总存金额 | RV2: 充值人数 | RW2: 存款 | RX2: 提款 | RY2: 存提差 | RZ2: 外部人员工资 | SA2: - | SB2: 平台盈亏 | SC2: 充值手续费3.5% | SD2: 平台服务费10% | SE2: 现场人员工资 | SF2: 净利润 | SG2: 人均客单价 | SH2: 支出回报率 | SI2: 投产比 | SM2: 平台 | SN2: 人数 | SO2: 注册 | SP2: 首存 | SQ2: 首存/总存金额 | SR2: 充值人数 | SS2: 存款 | ST2: 提款 | SU2: 存提差 | SV2: 外部人员工资 | SW2: - | SX2: 平台盈亏 | SY2: 充值手续费3.5% | SZ2: 平台服务费10% | TA2: 现场人员工资 | TB2: 净利润 | TC2: 人均客单价 | TD2: 支出回报率 | TE2: 投产比 | TH2: 平台 | TI2: 人数 | TJ2: 注册 | TK2: 首存 | TL2: 首存/总存金额 | TM2: 充值人数 | TN2: 存款 | TO2: 提款 | TP2: 存提差 | TQ2: 外部人员工资 | TR2: - | TS2: 平台盈亏 | TT2: 充值手续费4% | TU2: 平台服务费10% | TV2: 现场人员工资 | TW2: 净利润 | TX2: 人均客单价 | TY2: 支出回报率 | TZ2: 投产比 | UD2: 平台 | UE2: 人数 | UF2: 注册 | UG2: 首存 | UH2: 首存/总存金额 | UI2: 充值人数 | UJ2: 存款 | UK2: 提款 | UL2: 存提差 | UM2: 外部人员工资 | UN2: - | UO2: 平台盈亏 | UP2: 充值手续费4% | UQ2: 平台服务费10% | UR2: 现场人员工资 | US2: 净利润 | UT2: 人均客单价 | UU2: 支出回报率 | UV2: 投产比 | UZ2: 平台 | VA2: 人数 | VB2: 注册 | VC2: 首存 | VD2: 首存/总存金额 | VE2: 充值人数 | VF2: 存款 | VG2: 提款 | VH2: 存提差 | VI2: 外部人员工资 | VJ2: - | VK2: 平台盈亏 | VL2: 充值手续费4% | VM2: 平台服务费10% | VN2: 现场人员工资 | VO2: 净利润 | VP2: 人均客单价 | VQ2: 支出回报率 | VR2: 投产比
C3: Platform | D3: Onsite HC | E3: Transfer HC | F3: Online HC | G3: Avg FTD | H3: Total Reg | I3: Total FTD | J3: FTD Amt | K3: Total FTD Amt | L3: Total WD Amt | M3: New Dep | N3: New WD | O3: New Net | P3: L1 FTD | Q3: L1 Dep | R3: L1 WD | S3: Dep Users | T3: Re-Dep Users | U3: Dep | V3: WD | W3: Net Dep | X3: Online Salary | Y3: Platform P/L | Z3: Dep Fee 3.5% | AA3: Platform Fee 20% | AB3: Onsite Salary | AC3: Transfer Salary | AD3: Net Profit | AE3: New AOV | AF3: AOV | AG3: ROAS | AH3: ROI | AJ3: Platform | AK3: Onsite HC | AL3: Transfer HC | AM3: Online HC | AN3: Avg FTD | AO3: Total Reg | AP3: Total FTD | AQ3: FTD Amt | AR3: Total FTD Amt | AS3: Total WD Amt | AT3: New Dep | AU3: New WD | AV3: New Net | AW3: L1 FTD | AX3: L1 Dep | AY3: L1 WD | AZ3: Dep Users | BA3: Re-Dep Users | BB3: Dep | BC3: WD | BD3: Net Dep | BE3: Online Salary | BF3: Platform P/L | BG3: Dep Fee 3.5% | BH3: Platform Fee 20% | BI3: Onsite Salary | BJ3: Transfer Salary | BK3: Net Profit | BL3: New AOV | BM3: AOV | BN3: ROAS | BO3: ROI | BQ3: Platform | BR3: Onsite HC | BS3: Transfer HC | BT3: Online HC | BU3: Avg FTD | BV3: Total Reg | BW3: Total FTD | BX3: FTD Amt | BY3: Total FTD Amt | BZ3: Total WD Amt | CA3: New Dep | CB3: New WD | CC3: New Net | CD3: L1 FTD | CE3: L1 Dep | CF3: L1 WD | CG3: Dep Users | CH3: Re-Dep Users | CI3: Dep | CJ3: WD | CK3: Net Dep | CL3: Online Salary | CM3: Platform P/L | CN3: Dep Fee 3.5% | CO3: Platform Fee 20% | CP3: Onsite Salary | CQ3: Transfer Salary | CR3: Net Profit | CS3: New AOV | CT3: AOV | CU3: ROAS | CV3: ROI | CX3: Platform | CY3: Onsite HC | CZ3: Transfer HC | DA3: Online HC | DB3: Avg FTD | DC3: Total Reg | DD3: Total FTD | DE3: FTD Amt | DF3: Total FTD Amt | DG3: Total WD Amt | DH3: New Dep | DI3: New WD | DJ3: New Net | DK3: L1 FTD | DL3: L1 Dep | DM3: L1 WD | DN3: Dep Users | DO3: Re-Dep Users | DP3: Dep | DQ3: WD | DR3: Net Dep | DS3: Online Salary | DT3: Platform P/L | DU3: Dep Fee 3.5% | DV3: Platform Fee 20% | DW3: Onsite Salary | DX3: Transfer Salary | DY3: Net Profit | DZ3: New AOV | EA3: AOV | EB3: ROAS | EC3: ROI | EE3: Platform | EF3: Onsite HC | EG3: Transfer HC | EH3: Online HC | EI3: Avg FTD | EJ3: Total Reg | EK3: Total FTD | EL3: FTD Amt | EM3: Total FTD Amt | EN3: Total WD Amt | EO3: New Dep | EP3: New WD | EQ3: New Net | ER3: L1 FTD | ES3: L1 Dep | ET3: L1 WD | EU3: Dep Users | EV3: Re-Dep Users | EW3: Dep | EX3: WD | EY3: Net Dep | EZ3: Online Salary | FA3: Platform P/L | FB3: Dep Fee 3.5% | FC3: Platform Fee 20% | FD3: Onsite Salary | FE3: Transfer Salary | FF3: Net Profit | FG3: New AOV | FH3: AOV | FI3: ROAS | FJ3: ROI | FN3: Platform | FO3: Onsite HC | FP3: Transfer HC | FQ3: Online HC | FR3: Avg FTD | FS3: Total Reg | FT3: Total FTD | FU3: FTD Amt | FV3: Total FTD Amt | FW3: Total WD Amt | FX3: New Dep | FY3: New WD | FZ3: New Net | GA3: L1 FTD | GB3: L1 Dep | GC3: L1 WD | GD3: Dep Users | GE3: Re-Dep Users | GF3: Dep | GG3: WD | GH3: Net Dep | GI3: Online Salary | GJ3: Platform P/L | GK3: Dep Fee 3.5% | GL3: Platform Fee 20% | GM3: Onsite Salary | GN3: Transfer Salary | GO3: Net Profit | GP3: New AOV | GQ3: AOV | GR3: ROAS | GS3: ROI | GV3: Platform | GW3: Onsite HC | GX3: Transfer HC | GY3: Online HC | GZ3: Avg FTD | HA3: Total Reg | HB3: Total FTD | HC3: FTD Amt | HD3: Total FTD Amt | HE3: Total WD Amt | HF3: New Dep | HG3: New WD | HH3: New Net | HI3: L1 FTD | HJ3: L1 Dep | HK3: L1 WD | HL3: Dep Users | HM3: Re-Dep Users | HN3: Dep | HO3: WD | HP3: Net Dep | HQ3: Online Salary | HR3: Platform P/L | HS3: Dep Fee 3.5% | HT3: Platform Fee 20% | HU3: Onsite Salary | HV3: Transfer Salary | HW3: Net Profit | HX3: New AOV | HY3: AOV | HZ3: ROAS | IA3: ROI | ID3: Platform | IE3: Onsite HC | IF3: Transfer HC | IG3: Online HC | IH3: Avg FTD | II3: Total Reg | IJ3: Total FTD | IK3: FTD Amt | IL3: Total FTD Amt | IM3: Total WD Amt | IN3: New Dep | IO3: New WD | IP3: New Net | IQ3: L1 FTD | IR3: L1 Dep | IS3: L1 WD | IT3: Dep Users | IU3: Re-Dep Users | IV3: Dep | IW3: WD | IX3: Net Dep | IY3: Online Salary | IZ3: Platform P/L | JA3: Dep Fee 3.5% | JB3: Platform Fee 20% | JC3: Onsite Salary | JD3: Transfer Salary | JE3: Net Profit | JF3: New AOV | JG3: AOV | JH3: ROAS | JI3: ROI | JL3: Platform | JM3: Onsite HC | JN3: Transfer HC | JO3: Online HC | JP3: Avg FTD | JQ3: Total Reg | JR3: Total FTD | JS3: FTD Amt | JT3: Total FTD Amt | JU3: Total WD Amt | JV3: New Dep | JW3: New WD | JX3: New Net | JY3: L1 FTD | JZ3: L1 Dep | KA3: L1 WD | KB3: Dep Users | KC3: Re-Dep Users | KD3: Dep | KE3: WD | KF3: Net Dep | KG3: Online Salary | KH3: Platform P/L | KI3: Dep Fee 3.5% | KJ3: Platform Fee 20% | KK3: Onsite Salary | KL3: Transfer Salary | KM3: Net Profit | KN3: New AOV | KO3: AOV | KP3: ROAS | KQ3: ROI | KT3: Platform | KU3: Onsite HC | KV3: Transfer HC | KW3: Online HC | KX3: Avg FTD | KY3: Total Reg | KZ3: Total FTD | LA3: FTD Amt | LB3: Total FTD Amt | LC3: Total WD Amt | LD3: New Dep | LE3: New WD | LF3: New Net | LG3: L1 FTD | LH3: L1 Dep | LI3: L1 WD | LJ3: Dep Users | LK3: Re-Dep Users | LL3: Dep | LM3: WD | LN3: Net Dep | LO3: Online Salary | LP3: Platform P/L | LQ3: Dep Fee 3.5% | LR3: Platform Fee 20% | LS3: Onsite Salary | LT3: Transfer Salary | LU3: Net Profit | LV3: New AOV | LW3: AOV | LX3: ROAS | LY3: ROI | MB3: Platform | MC3: Onsite HC | MD3: Transfer HC | ME3: Online HC | MF3: Avg FTD | MG3: Total Reg | MH3: Total FTD | MI3: FTD Amt | MJ3: Total FTD Amt | MK3: Total WD Amt | ML3: New Dep | MM3: New WD | MN3: New Net | MO3: L1 FTD | MP3: L1 Dep | MQ3: L1 WD | MR3: Dep Users | MS3: Re-Dep Users | MT3: Dep | MU3: WD | MV3: Net Dep | MW3: Online Salary | MX3: Platform P/L | MY3: Dep Fee 3.5% | MZ3: Platform Fee 20% | NA3: Onsite Salary | NB3: Transfer Salary | NC3: Net Profit | ND3: New AOV | NE3: AOV | NF3: ROAS | NG3: ROI | NJ3: Platform | NK3: Onsite HC | NL3: Transfer HC | NM3: Online HC | NN3: Avg FTD | NO3: Total Reg | NP3: Total FTD | NQ3: FTD Amt | NR3: Total FTD Amt | NS3: Total WD Amt | NT3: New Dep | NU3: New WD | NV3: New Net | NW3: L1 FTD | NX3: L1 Dep | NY3: L1 WD | NZ3: Dep Users | OA3: Re-Dep Users | OB3: Dep | OC3: WD | OD3: Net Dep | OE3: Online Salary | OF3: Platform P/L | OG3: Dep Fee 3.5% | OH3: Platform Fee 20% | OI3: Onsite Salary | OJ3: Transfer Salary | OK3: Net Profit | OL3: New AOV | OM3: AOV | ON3: ROAS | OO3: ROI | OS3: Platform | OT3: Onsite HC | OU3: Online HC | OV3: Total Reg | OW3: Total FTD | OX3: FTD Amt | OY3: Total FTD Amt | OZ3: Total WD Amt | PA3: New Dep | PB3: New WD | PC3: Dep Users | PD3: Re-Dep Users | PE3: Dep | PF3: WD | PG3: Net Dep | PH3: Online Salary | PI3: Platform P/L | PJ3: Dep Fee 3.5% | PK3: Platform Fee 20% | PL3: Onsite Salary | PM3: Net Profit | PN3: New AOV | PO3: AOV | PP3: ROAS | PQ3: ROI | PS3: 异常提款 | PU3: Platform | PV3: Mainpower | PX3: Register | PY3: FTD | QA3: Ftd Total All DPS Amount | QC3: Depositors | QE3: Deposit | QF3: Withdraw | QG3: Different | QH3: WFH Staff Salary | QI3: Platform Profit | QJ3: Deposit Fee 3.5% | QK3: Platform Service Fee 10% | QL3: Office Staff Salary | QM3: Net Profit | QO3: Average Spend per Customer | QP3: Return on Advertising Spend | QQ3: Return on Investment % | QS3: 玩家异常提款： | QU3: Platform | QV3: Mainpower | QW3: Register | QX3: FTD | QY3: Ftd Total All DPS Amount | QZ3: Depositors | RA3: Deposit | RB3: Withdraw | RC3: Withdraw | RD3: Different | RE3: WFH Staff Salary | RF3: Platform Profit | RG3: Deposit Fee 3.5% | RH3: Platform Service Fee 10% | RI3: Office Staff Salary | RJ3: Net Profit | RK3: Average Spend per Customer | RL3: Return on Advertising Spend | RM3: Return on Investment % | RQ3: Platform | RR3: Mainpower | RS3: Register | RT3: FTD | RU3: Ftd Total All DPS Amount | RV3: Depositors | RW3: Deposit | RX3: Withdraw | RY3: Different | RZ3: WFH Staff Salary | SA3: - | SB3: Platform Profit | SC3: Deposit Fee 3.5% | SD3: Platform Service Fee 10% | SE3: Office Staff Salary | SF3: Net Profit | SG3: Average Spend per Customer | SH3: Return on Advertising Spend | SI3: Return on Investment % | SM3: Platform | SN3: Mainpower | SO3: Register | SP3: FTD | SQ3: Ftd Total All DPS Amount | SR3: Depositors | SS3: Deposit | ST3: Withdraw | SU3: Different | SV3: WFH Staff Salary | SW3: - | SX3: Platform Profit | SY3: Deposit Fee 3.5% | SZ3: Platform Service Fee 10% | TA3: Office Staff Salary | TB3: Net Profit | TC3: Average Spend per Customer | TD3: Return on Advertising Spend | TE3: Return on Investment % | TH3: Platform | TI3: Mainpower | TJ3: Register | TK3: FTD | TL3: Ftd Total All DPS Amount | TM3: Depositors | TN3: Deposit | TO3: Withdraw | TP3: Different | TQ3: WFH Staff Salary | TR3: - | TS3: Platform Profit | TT3: Deposit Fee 3.5% | TU3: Platform Service Fee 10% | TV3: Office Staff Salary | TW3: Net Profit | TX3: Average Spend per Customer | TY3: Return on Advertising Spend | TZ3: Return on Investment % | UD3: Platform | UE3: Mainpower | UF3: Register | UG3: FTD | UH3: Ftd Total All DPS Amount | UI3: Depositors | UJ3: Deposit | UK3: Withdraw | UL3: Different | UM3: WFH Staff Salary | UN3: - | UO3: Platform Profit | UP3: Deposit Fee 3.5% | UQ3: Platform Service Fee 10% | UR3: Office Staff Salary | US3: Net Profit | UT3: Average Spend per Customer | UU3: Return on Advertising Spend | UV3: Return on Investment % | UZ3: Platform | VA3: Mainpower | VB3: Register | VC3: FTD | VD3: Ftd Total All DPS Amount | VE3: Depositors | VF3: Deposit | VG3: Withdraw | VH3: Different | VI3: WFH Staff Salary | VJ3: - | VK3: Platform Profit | VL3: Deposit Fee 3.5% | VM3: Platform Service Fee 10% | VN3: Office Staff Salary | VO3: Net Profit | VP3: Average Spend per Customer | VQ3: Return on Advertising Spend | VR3: Return on Investment %
C4: PH09 | D4: 3 | E4: 2 | F4: ='PH09'!AJ4 -> 45 | G4: =(I4/F4)/S1 -> 4.6803419 | H4: ='PH09'!G4 -> 9462 | I4: ='PH09'!H4 -> 5476 | J4: ='PH09'!T4 -> 829366 | K4: ='PH09'!U4 -> 1150492 | L4: ='[1]PH09'!V4 -> 666493.12 | M4: =1379384+1309192 -> 2688576 | N4: =1296422.25+1155050 -> 2451472.2 | O4: =M4-N4 -> 237103.75 | P4: ='PH09'!J4 -> 4267 | Q4: ='PH09'!R4 -> 895925 | R4: ='PH09'!S4 -> 670308.88 | S4: ='PH09'!K4 -> 37917 | T4: =S4-I4 -> 32441 | U4: ='PH09'!W4 -> 25783720 | V4: ='PH09'!X4 -> 21822575 | W4: =U4-V4 -> 3961145.4 | X4: ='PH09'!D4 -> 981915 | Y4: =2980321.9+651197.33 -> 3631519.2 | Z4: =U4*3.5% -> 902430.2 | AA4: =IF(Y4>0,Y4*20%,0) -> 726303.85 | AB4: =(D4*3200)*S1 -> 249600 | AC4: =(E4*1733)*S1 -> 90116 | AD4: =W4-Z4-AA4-X4-AB4-AC4 -> 1010780.3 | AE4: =K4/I4 -> 210.09715 | AF4: =U4/S4 -> 680.00422 | AG4: =M4/(Z4+AA4+X4+AB4+AC4) -> 0.91126893 | AH4: =W4/(Z4+AA4+X4+AB4+AC4) -> 1.342595 | AJ4: PH09 | AK4: 1 | AL4: 2 | AM4: 66 | AN4: =(AP4/AM4)/AZ1 -> 3.0616162 | AO4: 11277 | AP4: 6062 | AQ4: 888457 | AR4: 1207999 | AS4: 860977.4 | AT4: 3346155 | AU4: 2829610.8 | AV4: =AT4-AU4 -> 516544.18 | AW4: 1006928 | AX4: 1006928 | AY4: 707035.4 | AZ4: 43237 | BA4: 37175 | BB4: 27807396 | BC4: 23414005 | BD4: =BB4-BC4 -> 4393391.2 | BE4: 902275 | BF4: 4291954.7 | BG4: =BB4*3.5% -> 973258.86 | BH4: =IF(BF4>0,BF4*20%,0) -> 858390.93 | BI4: =(AK4*3200)*AZ1 -> 96000 | BJ4: =(AL4*1733)*AZ1 -> 103980 | BK4: =BD4-BG4-BH4-BE4-BI4-BJ4 -> 1459486.4 | BL4: =AR4/AP4 -> 199.274 | BM4: =BB4/AZ4 -> 643.13889 | BN4: =AT4/(BG4+BH4+BE4+BI4) -> 1.1824183 | BO4: =BD4/(BG4+BH4+BE4+BI4+BJ4) -> 1.4974553 | BQ4: PH09 | BR4: 1 | BS4: 2 | BT4: 68 | BU4: 2.2969639 | BV4: 10666 | BW4: 4842 | BX4: 770219 | BY4: 1085316 | BZ4: 742565.75 | CA4: 3937326 | CB4: 3888711.9 | CC4: 48614.09 | CD4: 4060 | CE4: 891415 | CF4: 604527.8 | CG4: 41794 | CH4: 38285 | CI4: 29140944 | CJ4: 24995726 | CK4: =CI4-CJ4 -> 4145218 | CL4: 742860 | CM4: 3662705.5 | CN4: =CI4*3.5% -> 1019933 | CO4: =IF(CM4>0,CM4*20%,0) -> 732541.11 | CP4: =(BR4*3200)*CI1 -> 99200 | CQ4: =(BS4*1733)*CI1 -> 107446 | CR4: =CK4-CN4-CO4-CL4-CP4-CQ4 -> 1443237.9 | CS4: =BY4/BW4 -> 224.14622 | CT4: =CI4/CG4 -> 697.25185 | CU4: =CA4/(CN4+CO4+CL4+CP4) -> 1.5175464 | CV4: =CK4/(CN4+CO4+CL4+CP4+CQ4) -> 1.5341408 | CX4: PH09 | CY4: 1 | CZ4: 0 | DA4: 54 | DB4: 2.9345679 | DC4: 9056 | DD4: 4754 | DE4: 679684 | DF4: 900282 | DG4: 557096.5 | DH4: 2556554 | DI4: 2330008.1 | DJ4: =DH4-DI4 -> 226545.88 | DK4: 4028 | DL4: 740980 | DM4: 466823.8 | DN4: 44966 | DO4: 40212 | DP4: 27624918 | DQ4: 25212389 | DR4: =DP4-DQ4 -> 2412529 | DS4: 793280 | DT4: 2008792.4 | DU4: =DP4*3.5% -> 966872.13 | DV4: =IF(DT4>0,DT4*20%,0) -> 401758.48 | DW4: =(CY4*3200)*DP1 -> 96000 | DX4: =(CZ4*1733)*DP1 -> 0 | DY4: =DR4-DU4-DV4-DS4-DW4-DX4 -> 154618.39 | DZ4: =DF4/DD4 -> 189.37358 | EA4: =DP4/DN4 -> 614.35124 | EB4: =DH4/(DU4+DV4+DS4+DW4) -> 1.1322654 | EC4: =DR4/(DU4+DV4+DS4+DW4+DX4) -> 1.0684785 | EE4: PH09 | EF4: 2 | EG4: 0 | EH4: 56 | EI4: 3.8778802 | EJ4: 12711 | EK4: 6732 | EL4: 999267 | EM4: 1357410 | EN4: 830117.5 | EO4: 3444254 | EP4: 2898980.5 | EQ4: 545273.5 | ER4: 5573 | ES4: 1145516 | ET4: 668323 | EU4: 54550 | EV4: 47818 | EW4: 29505387 | EX4: 25972679 | EY4: 3532708 | EZ4: 1099330 | FA4: 3059662.1 | FB4: =EW4*3.5% -> 1032688.5 | FC4: =FA4*20% -> 611932.43 | FD4: =(EF4*3200)*EW1 -> 198400 | FE4: =(EG4*1733)*EW1 -> 0 | FF4: 512253.03 | FG4: 201.63547 | FH4: 540.88702 | FI4: 1.157578 | FJ4: 1.1695947 | FN4: PH09 | FO4: 2 | FP4: 2 | FQ4: 91 | FR4: =(FT4/FQ4)/GF1 -> 3.2366562 | FS4: 16683 | FT4: 8247 | FU4: 1265120 | FV4: 1814282 | FW4: 1247205 | FX4: 6084614 | FY4: 5961969 | FZ4: =FX4-FY4 -> 122645 | GA4: 6720 | GB4: 1533163 | GC4: 1013578 | GD4: 61216 | GE4: 52969 | GF4: 32341719 | GG4: 29693868 | GH4: 2647851 | GI4: 1199250 | GJ4: 2324928.2 | GK4: 1131960.2 | GL4: 464985.64 | GM4: =(FO4*3200)*GF1 -> 179200 | GN4: =(FP4*1733)*GF1 -> 97048 | GO4: -454440.8 | GP4: 219.99297 | GQ4: 528.32134 | GR4: =FX4/(GK4+GL4+GI4+GM4) -> 2.0449763 | GS4: =GH4/(GK4+GL4+GI4+GM4+GN4) -> 0.86180616 | GV4: PH09 | GW4: 2 | GX4: 2 | GY4: 58 | GZ4: =(HB4/GY4)/HL1 -> 4.416574 | HA4: 16975 | HB4: 7941 | HC4: 1238681 | HD4: 1831129 | HE4: 1266189 | HF4: 5391677 | HG4: 5097164 | HH4: =HF4-HG4 -> 294513 | HI4: 6378 | HJ4: 1485963 | HK4: 1020087 | HL4: 69375 | HM4: 61434 | HN4: 35674099 | HO4: 32415093 | HP4: 3259006 | HQ4: 1253970 | HR4: 2951240.3 | HS4: 1248593.5 | HT4: 102961.03 | HU4: =(GW4*3200)*31 -> 198400 | HV4: =(GX4*1733)*31 -> 107446 | HW4: 314589.51 | HX4: 230.59174 | HY4: 514.22125 | HZ4: =HF4/(HS4+HT4+HQ4+HU4) -> 1.9229038 | IA4: =HP4/(HS4+HT4+HQ4+HU4+HV4) -> 1.1194061 | ID4: PH09 | IE4: 5 | IF4: 0 | IG4: 71 | IH4: =(IJ4/IG4)/IT1 -> 4.1440254 | II4: 20971 | IJ4: 9121 | IK4: 1451145 | IL4: 2090288 | IM4: 1312613.6 | IN4: 6534114.9 | IO4: 5871295.6 | IP4: =IN4-IO4 -> 662819.3 | IQ4: 7314 | IR4: 1702261 | IS4: 1040854 | IT4: 79569 | IU4: 70448 | IV4: 42115966 | IW4: 36314609 | IX4: =IV4-IW4 -> 5801357.4 | IY4: 1177430 | IZ4: 5044170.5 | JA4: =IV4*3.5% -> 1474058.8 | JB4: =IZ4*20% -> 1008834.1 | JC4: 301542 | JD4: 0 | JE4: =IX4-JA4-JB4-IY4-JC4 -> 1839492.4 | JF4: =IL4/IJ4 -> 229.17312 | JG4: =IV4/IT4 -> 529.30119 | JH4: =IL4/(JA4+JB4+IY4+JC4) -> 0.52760204 | JI4: =IX4/(JA4+JB4+IY4+JC4) -> 1.4642996 | JL4: PH09 | JM4: 6 | JN4: 0 | JO4: 78 | JP4: =(JR4/JO4)/KB1 -> 2.7837607 | JQ4: 19053 | JR4: 6514 | JS4: 1018622 | JT4: 1391848 | JU4: 802364 | JV4: 3087973 | JW4: 2335691 | JX4: =JV4-JW4 -> 752282 | JY4: 5411 | JZ4: 1110685 | KA4: 595930 | KB4: 59831 | KC4: 53317 | KD4: 32700069 | KE4: 27732806 | KF4: =KD4-KE4 -> 4967263 | KG4: 1057260 | KH4: 4611073.9 | KI4: =KD4*3.5% -> 1144502.4 | KJ4: =KH4*20% -> 922214.78 | KK4: 311940 | KL4: 0 | KM4: =KF4-KI4-KJ4-KG4-KK4 -> 1531345.8 | KN4: =JT4/JR4 -> 213.67025 | KO4: =KD4/KB4 -> 546.54057 | KP4: =JT4/(KI4+KJ4+KG4+KK4) -> 0.40508776 | KQ4: =KF4/(KI4+KJ4+KG4+KK4) -> 1.4456876 | KT4: PH09 | KU4: 6 | KV4: 0 | KW4: 231 | KX4: =(KZ4/KW4)/LJ1 -> 1.7295071 | KY4: 33171 | KZ4: 12385 | LA4: 1916641 | LB4: 2855776 | LC4: 1824188 | LD4: 8110593 | LE4: 6917018 | LF4: =LE4 -> 6917018 | LG4: 9925 | LH4: 2304912 | LI4: 1432878 | LJ4: 92176 | LK4: 79791 | LL4: 45380021 | LM4: 38099220 | LN4: 7280801 | LO4: 1477360 | LP4: 6805456.4 | LQ4: 1588300.7 | LR4: 1361091.3 | LS4: 322338 | LT4: 0 | LU4: 2531711 | LV4: 230.58345 | LW4: 492.31927 | LX4: 0.6013312 | LY4: 1.5330939 | MB4: PH09 | MC4: 7 | MD4: 0 | ME4: 306 | MF4: =(MH4/ME4)/MR1 -> 2.5518519 | MG4: 69667 | MH4: 23426 | MI4: 3480755 | MJ4: 5384982 | MK4: 3595018 | ML4: 15019924 | MM4: 12445640 | MN4: =ML4-MM4 -> 2574284.4 | MO4: 18854 | MP4: 4390192 | MQ4: 2688747 | MR4: 111717 | MS4: 88291 | MT4: 48487088 | MU4: 39856326 | MV4: =MT4-MU4 -> 8630762 | MW4: 2031430 | MX4: 8135533 | MY4: =MT4*3.5% -> 1697048.1 | MZ4: =MX4*20% -> 1627106.6 | NA4: 363930 | NB4: =MV4-MY4-MZ4-MW4-NA4 -> 2911247.3 | NC4: 0 | ND4: =MJ4/MH4 -> 229.87202 | NE4: =MT4/MR4 -> 434.0171 | NF4: =MJ4/(MY4+MZ4+MW4+NA4) -> 0.9415103 | NG4: =MV4/(MY4+MZ4+MW4+NA4) -> 1.5090025 | NJ4: PH09 | NK4: 7 | NL4: 0 | NM4: 247 | NN4: =(NP4/NM4)/NZ1 -> 3.0506726 | NO4: 55995 | NP4: 23359 | NQ4: 3334508 | NR4: 5051782 | NS4: 3245513 | NT4: 14020716 | NU4: 11195306 | NV4: =NT4-NU4 -> 2825410 | NW4: 18559 | NX4: 4048818 | NY4: 2541617 | NZ4: 117490 | OA4: =NZ4-NP4 -> 94131 | OB4: 48043927 | OC4: 40150658 | OD4: =OB4-OC4 -> 7893269 | OE4: 2231090 | OF4: 7017500.7 | OG4: =OB4*3.5% -> 1681537.4 | OH4: =OF4*20% -> 1403500.1 | OI4: 389925 | OJ4: 0 | OK4: =OD4-OG4-OH4-OE4-OI4 -> 2187216.4 | OL4: =NR4/NP4 -> 216.26705 | OM4: =OB4/NZ4 -> 408.91929 | ON4: =NR4/(OG4+OH4+OE4+OI4) -> 0.88533744 | OO4: =OD4/(OG4+OH4+OE4+OI4) -> 1.3833152 | OS4: PH09 | OT4: 7 | OU4: 365 | OV4: 84885 | OW4: 37089 | OX4: 5193519 | OY4: 7227060 | OZ4: 4253474 | PA4: 18428987 | PB4: 14729529 | PC4: 141267 | PD4: 104178 | PE4: 51384327 | PF4: 41982348 | PG4: =PE4-PF4 -> 9401979 | PH4: 3400670 | PI4: 8059405.1 | PJ4: =PE4*3.5% -> 1798451.4 | PK4: =PI4*20% -> 1611881 | PL4: =OT4*1733*PF1+1 -> 376062 | PM4: =PG4-PJ4-PK4-PH4-PL4 -> 2214914.5 | PN4: =OY4/OW4 -> 194.85724 | PO4: =PE4/PC4 -> 363.73907 | PP4: =OY4/(PH4+PJ4+PK4+PL4) -> 1.0055649 | PQ4: =PG4/(PJ4+PK4+PH4+PL4) -> 1.3081807 | PU4: PH09 | PV4: 7 | PW4: 523 | PX4: 91325 | PY4: 36534 | PZ4: 5261580 | QA4: 7247298 | QB4: 4224782 | QC4: 133093 | QD4: 96559 | QE4: 47902598 | QF4: 41952271 | QG4: 5950327 | QH4: 3697460 | QI4: 4193645.5 | QJ4: =QE4*3.5% -> 1676590.9 | QK4: =QI4*20% -> 838729.1 | QL4: =PV4*3306*QG1+1 -> 694261 | QM4: =QG4-QJ4-QK4 -> 3435007 | QN4: =PZ4/PY4 -> 144.01872 | QO4: =QE4/QC4 -> 359.91824 | QP4: =QA4/(QH4+QJ4+QK4+QL4) -> 1.0492623 | QQ4: =QG4/(QJ4+QK4) -> 2.3656342 | QR4: 披索 | QS4: 303213.11 | QT4: 5-01玩家提款：31,751.17/ 5-14玩家提款：273,883.59 + 109,767.49/ 5-16大客提款：25,021.73/ 5-24玩家提款：85,500.93 + 20,943.89 + 20,106.13/ 5-28玩家提款：105,574.71 总提款= 672,549.64 | QU4: PH09 | QV4: 6 | QW4: 97858 | QX4: 36306 | QY4: 17609748 | QZ4: 54338 | RA4: 49818115 | RB4: 43272062 | RC4: =RB4-RE4 -> 40116122 | RD4: =RA4-RC4 -> 9701992.9 | RE4: 3155940 | RF4: 5061477.3 | RG4: =RA4*3.5% -> 1743634 | RH4: =RF4*10% -> 506147.73 | RI4: =QV4*3306*31 -> 614916 | RJ4: =RD4-RG4-RH4 -> 7452211.1 | RK4: =RA4/QZ4 -> 916.81908 | RL4: =QY4/(RE4+RG4+RH4+RI4) -> 2.9248974 | RM4: =RD4/(RG4+RH4) -> 4.3124151 | RQ4: PH09 | RR4: 6 | RS4: 100622 | RT4: 30267 | RU4: 17609748 | RV4: 51424 | RW4: 44335230 | RX4: 38764713 | RY4: =RW4-RX4 -> 5570517 | RZ4: 2809020 | SA4: 0 | SB4: 4103408.8 | SC4: =RW4*3.5% -> 1551733.1 | SD4: =SB4*10% -> 410340.88 | SE4: =RR4*3306*30 -> 595080 | SF4: =RY4-SC4-SD4-SE4 -> 3013363.1 | SG4: =RW4/RV4 -> 862.15055 | SH4: =RU4/(RZ4+SC4+SD4+SE4) -> 3.2816208 | SI4: =RY4/(SC4+SD4+SE4) -> 2.178405 | SM4: PH09 | SN4: 6 | SO4: 102338 | SP4: 34205 | SQ4: 16317065 | SR4: 48451 | SS4: 45913823 | ST4: 41190794 | SU4: =SS4-ST4 -> 4723029.2 | SV4: 3323280 | SW4: 0 | SX4: 3655223 | SY4: =SS4*3.5% -> 1606983.8 | SZ4: =SX4*10% -> 365522.3 | TA4: =SN4*4000*31 -> 744000 | TB4: =SU4-SY4-SZ4-TA4 -> 2006523.1 | TC4: =SS4/SR4 -> 947.63417 | TD4: =SQ4/(SV4+SY4+SZ4+TA4) -> 2.7015964 | TE4: =SU4/(SY4+SZ4+TA4) -> 1.7386411 | TH4: PH09 | TI4: 7 | TJ4: 95013 | TK4: 32302 | TL4: 15575511 | TM4: 44925 | TN4: 39279311 | TO4: 36616179 | TP4: =TN4-TO4 -> 2663131.6 | TQ4: 3609840 | TR4: 0 | TS4: 2501870.9 | TT4: =TN4*4% -> 1571172.4 | TU4: =TS4*10% -> 250187.09 | TV4: =TI4*4000*28 -> 784000 | TW4: =TP4-TT4-TU4-TV4 -> 57772.07 | TX4: =TN4/TM4 -> 874.33079 | TY4: =TL4/(TQ4+TT4+TU4+TV4) -> 2.5060356 | TZ4: =TP4/(TT4+TU4+TV4) -> 1.0221743 | UD4: PH09 | UE4: 7 | UF4: 100544 | UG4: 32866 | UH4: 18440364 | UI4: 45284 | UJ4: 42920731 | UK4: 39723751 | UL4: =UJ4-UK4 -> 3196979.7 | UM4: 3285990 | UN4: 0 | UO4: 2318924 | UP4: =UJ4*4% -> 1716829.2 | UQ4: =UO4*10% -> 231892.39 | UR4: =UE4*4000*31 -> 868000 | US4: =UL4-UP4-UQ4-UR4 -> 380258.06 | UT4: =UJ4/UI4 -> 947.81227 | UU4: =UH4/(UM4+UP4+UQ4+UR4) -> 3.0216672 | UV4: =UL4/(UP4+UQ4+UR4) -> 1.1350002 | UZ4: PH09 | VA4: 7 | VB4: 94446 | VC4: 31254 | VD4: 18784599 | VE4: 41725 | VF4: 42382252 | VG4: 42892684 | VH4: =VF4-VG4 -> -510432.02 | VI4: 2865865 | VJ4: 0 | VK4: -1362500.4 | VL4: =VF4*4% -> 1695290.1 | VM4: 0 | VN4: =VA4*4000*31 -> 868000 | VO4: =VH4-VL4-VM4-VN4 -> -3073722.1 | VP4: =VF4/VE4 -> 1015.752 | VQ4: =VD4/(VI4+VL4+VM4+VN4) -> 3.4599488 | VR4: =VH4/(VL4+VM4+VN4) -> -0.19913159
C5: PH09-2 | AJ5: PH09-2 | BQ5: PH09-2 | BR5: 1 | BS5: 2 | BT5: 14 | BU5: 1.1428571 | BV5: 904 | BW5: 496 | BX5: 74657 | BY5: 770219 | BZ5: 80032 | CA5: 228677 | CB5: 195273 | CC5: 33404 | CD5: 427 | CE5: 88414 | CF5: 71196 | CG5: 3363 | CH5: 2867 | CI5: 1882774 | CJ5: 1454411 | CK5: =CI5-CJ5 -> 428363 | CL5: 55620 | CM5: 417270.92 | CN5: =CI5*3.5% -> 65897.09 | CO5: =IF(CM5>0,CM5*20%,0) -> 83454.184 | CP5: =(BR5*3200)*CI1 -> 99200 | CQ5: =(BS5*1733)*CI1 -> 107446 | CR5: =CK5-CN5-CO5-CL5-CP5-CQ5 -> 16745.726 | CS5: =BY5/BW5 -> 1552.8609 | CT5: =CI5/CG5 -> 559.84954 | CU5: =CA5/(CN5+CO5+CL5+CP5) -> 0.75180341 | CV5: =CK5/(CN5+CO5+CL5+CP5+CQ5) -> 1.0406828 | CX5: PH09-2 | CY5: 1 | CZ5: 2 | DA5: 19 | DB5: 1.4105263 | DC5: 1599 | DD5: 804 | DE5: 133621 | DF5: 679684 | DG5: 119260.95 | DH5: 437733 | DI5: 386719.95 | DJ5: =DH5-DI5 -> 51013.05 | DK5: 715 | DL5: 157493 | DM5: 108568.95 | DN5: 4678 | DO5: 3874 | DP5: 2231956 | DQ5: 1929115 | DR5: =DP5-DQ5 -> 302841 | DS5: 125950 | DT5: 259760.52 | DU5: =DP5*3.5% -> 78118.46 | DV5: =IF(DT5>0,DT5*20%,0) -> 51952.104 | DW5: =(CY5*3200)*DP1 -> 96000 | DX5: =(CZ5*1733)*DP1 -> 103980 | DY5: =DR5-DU5-DV5-DS5-DW5-DX5 -> -153159.56 | DZ5: =DF5/DD5 -> 845.37811 | EA5: =DP5/DN5 -> 477.11757 | EB5: =DH5/(DU5+DV5+DS5+DW5) -> 1.243487 | EC5: =DR5/(DU5+DV5+DS5+DW5+DX5) -> 0.66412418 | EE5: PH09-2 | EF5: 2 | EG5: 2 | EH5: 35 | EI5: 2.1898618 | EJ5: 4029 | EK5: 2376 | EL5: 353665 | EM5: 999267 | EN5: 266444 | EO5: 1012728 | EP5: 944540 | EQ5: 68188 | ER5: 2123 | ES5: 409413 | ET5: 239059 | EU5: 8699 | EV5: 6323 | EW5: 3565118 | EX5: 3042028 | EY5: 523090 | EZ5: 325240 | FA5: 460089.75 | FB5: 124779.13 | FC5: 92017.95 | FD5: =(EF5*3200)*EW1 -> 198400 | FE5: =(EG5*1733)*EW1 -> 107446 | FF5: -357839.08 | FG5: 420.56692 | FH5: 409.83079 | FI5: 1.3093085 | FJ5: 0.59379354 | FN5: PH09-2 | FO5: 2 | FP5: 2 | FQ5: 83 | FR5: =(FT5/FQ5)/GF1 -> 1.4229776 | FS5: 6443 | FT5: 3307 | FU5: 498795 | FV5: 1265120 | FW5: 453577 | FX5: 2727613 | FY5: 2873199 | FZ5: =FX5-FY5 -> -145586 | GA5: 2960 | GB5: 654904 | GC5: 409155 | GD5: 9792 | GE5: 6485 | GF5: 4306772 | GG5: 4383429 | GH5: -76657 | GI5: 255860 | GJ5: -172308.86 | GK5: 150737.02 | GL5: 0 | GM5: =(FO5*3200)*GF1 -> 179200 | GN5: =(FP5*1733)*GF1 -> 97048 | GO5: -789350.02 | GP5: 382.55821 | GQ5: 439.82557 | GR5: =FX5/(GK5+GL5+GI5+GM5) -> 4.6562425 | GS5: =GH5/(GK5+GL5+GI5+GM5+GN5) -> -0.1122612 | GV5: PH09-2 | GW5: 2 | GX5: 2 | GY5: 36 | GZ5: =(HB5/GY5)/HL1 -> 1.4139785 | HA5: 2993 | HB5: 1578 | HC5: 255690.22 | HD5: 305587 | HE5: 194082 | HF5: 815845 | HG5: 753481 | HH5: =HF5-HG5 -> 62364 | HI5: 1400 | HJ5: 262974 | HK5: 165798 | HL5: 5985 | HM5: 4407 | HN5: 2556760 | HO5: 2361932 | HP5: 194828 | HQ5: 106910 | HR5: 141617.22 | HS5: 89486.6 | HT5: 29721.344 | HU5: =(GW5*3200)*31 -> 198400 | HV5: =(GX5*1733)*31 -> 107446 | HW5: -370181.94 | HX5: 193.65463 | HY5: 427.19465 | HZ5: =HF5/(HS5+HT5+HQ5+HU5) -> 1.9218151 | IA5: =HP5/(HS5+HT5+HQ5+HU5+HV5) -> 0.36624287 | ID5: PH09-2 | IE5: 3 | IF5: 0 | IG5: 12 | IH5: =(IJ5/IG5)/IT1 -> 2.827957 | II5: 1883 | IJ5: 1052 | IK5: 147230 | IL5: 205763 | IM5: 125749 | IN5: 669065 | IO5: 641032 | IP5: =IN5-IO5 -> 28033 | IQ5: 932 | IR5: 177738 | IS5: 106734 | IT5: 5103 | IU5: 4051 | IV5: 2020978 | IW5: 1948689 | IX5: =IV5-IW5 -> 72289 | IY5: 75390 | IZ5: 46636.22 | JA5: =IV5*3.5% -> 70734.23 | JB5: =IZ5*20% -> 9327.244 | JC5: 161169 | JD5: 0 | JE5: =IX5-JA5-JB5-IY5-JC5 -> -244331.47 | JF5: =IL5/IJ5 -> 195.59221 | JG5: =IV5/IT5 -> 396.03723 | JH5: =IL5/(JA5+JB5+IY5+JC5) -> 0.64987269 | JI5: =IX5/(JA5+JB5+IY5+JC5) -> 0.22831436 | JL5: PH09-2 | JM5: 3 | JN5: 20 | JO5: 20 | JQ5: 1523 | JR5: 678 | JS5: 95981 | JT5: 133890 | JU5: 164430 | JV5: 295242 | JW5: 289044 | JX5: =JV5-JW5 -> 6198 | JY5: 544 | JZ5: 111429 | KA5: 92666 | KB5: 3880 | KC5: 3202 | KD5: 2678181 | KE5: 2233875 | KF5: =KD5-KE5 -> 444306 | KG5: 51780 | KH5: 479051.04 | KI5: =KD5*3.5% -> 93736.335 | KJ5: =KH5*20% -> 95810.208 | KK5: 155970 | KM5: =KF5-KI5-KJ5-KG5-KK5 -> 47009.457 | KN5: =JT5/JR5 -> 197.47788 | KO5: =KD5/KB5 -> 690.25284 | KP5: =JT5/(KI5+KJ5+KG5+KK5) -> 0.33700268 | KQ5: =KF5/(KI5+KJ5+KG5+KK5) -> 1.1183233 | KT5: PH09-2 | KU5: 3 | KW5: 71 | KY5: 3316 | KZ5: 1502 | LA5: 229851 | LB5: 331889 | LC5: 202390 | LD5: 815147 | LE5: 763027 | LF5: =LE5 -> 763027 | LG5: 1298 | LH5: 371405 | LI5: 229110 | LJ5: 6314 | LK5: 4812 | LL5: 3814842 | LM5: 4684513 | LN5: -869671 | LO5: 115140 | LP5: -871493.86 | LQ5: 133519.47 | LR5: 0 | LS5: 161169 | LU5: -1279499.5 | LV5: 220.96471 | LW5: 604.18784 | LX5: 0.80982417 | LY5: -2.1220366 | MB5: PH09-2 | MC5: 3 | ME5: 67 | MG5: 4654 | MH5: 2314 | MI5: 333138 | MJ5: 487443 | MK5: 333562 | ML5: 1353002 | MM5: 1025636 | MO5: 1975 | MP5: 407146 | MQ5: 265630 | MR5: 7517 | MS5: 5203 | MT5: 4683703 | MU5: 4058748 | MV5: =MT5-MU5 -> 624955 | MW5: 144420 | MX5: 574115.84 | MY5: =MT5*3.5% -> 163929.61 | MZ5: =MX5*20% -> 114823.17 | NA5: 169834 | NB5: =MV5-MY5-MZ5-MW5-NA5 -> 31948.227 | ND5: =MJ5/MH5 -> 210.64952 | NE5: =MT5/MR5 -> 623.08142 | NF5: =MJ5/(MY5+MZ5+MW5+NA5) -> 0.82198555 | NG5: =MV5/(MY5+MZ5+MW5+NA5) -> 1.053875 | NJ5: PH09-2 | NK5: 4 | NM5: 41 | NO5: 5663 | NP5: 2745 | NQ5: 390205 | NR5: 518864 | NS5: 347208 | NT5: 1235386 | NU5: 1041962 | NW5: 2337 | NX5: 438127 | NY5: 277775 | NZ5: 8156 | OA5: =NZ5-NP5 -> 5411 | OB5: 5423344 | OC5: 4603109 | OD5: =OB5-OC5 -> 820235 | OE5: 281580 | OF5: 673216.25 | OG5: =OB5*3.5% -> 189817.04 | OH5: =OF5*20% -> 134643.25 | OI5: 183698 | OK5: =OD5-OG5-OH5-OE5-OI5 -> 30496.71 | OL5: =NR5/NP5 -> 189.02149 | OM5: =OB5/NZ5 -> 664.95145 | ON5: =NR5/(OG5+OH5+OE5+OI5) -> 0.65700753 | OO5: =OD5/(OG5+OH5+OE5+OI5) -> 1.0386162 | OS5: PH09-2 | OT5: 2 | OU5: 57 | OV5: 7033 | OW5: 3511 | OX5: 508500 | OY5: 693167 | OZ5: 439928 | PA5: 1519533 | PB5: 1256288 | PC5: 9177 | PD5: 5666 | PE5: 4220235 | PF5: 3450673 | PG5: =PE5-PF5 -> 769562 | PH5: 318780 | PI5: 608186.35 | PJ5: =PE5*3.5% -> 147708.23 | PK5: =PI5*20% -> 121637.27 | PL5: =OT5*1733*PF1+1 -> 107447 | PM5: =PG5-PJ5-PK5-PH5-PL5 -> 73989.505 | PN5: =OY5/OW5 -> 197.42723 | PO5: =PE5/PC5 -> 459.87087 | PP5: =OY5/(PH5+PJ5+PK5+PL5) -> 0.9965417 | PQ5: =PG5/(PJ5+PK5+PH5+PL5) -> 1.1063721 | PU5: PH09-2 | PV5: 2 | PW5: 53 | PX5: 5332 | PY5: 2554 | PZ5: 385053 | QA5: 499804 | QB5: 294573 | QC5: 6940 | QD5: 4386 | QE5: 2509660 | QF5: 1929332 | QG5: 580328 | QH5: 215310 | QI5: 490437.98 | QJ5: =QE5*3.5% -> 87838.1 | QK5: =QI5*20% -> 98087.596 | QL5: =PV5*3306*QG1+1 -> 198361 | QM5: =QG5-QJ5-QK5 -> 394402.3 | QN5: =PZ5/PY5 -> 150.76468 | QO5: =QE5/QC5 -> 361.62248 | QP5: =QA5/(QH5+QJ5+QK5+QL5) -> 0.83356697 | QQ5: =QG5/(QJ5+QK5) -> 3.1212899 | QR5: 披索 | QT5: 5-01玩家提款：65,094.67/ 5-08玩家提款：77,014.39/ 5-22玩家提款：252,050.63/ 5-23玩家提款：721,994.11/ 5-24玩家提款：60,033.37/ 5-26玩家提款：106,918.90/ 5-28玩家提款：304,456.94 + 22,787.90 + 19,658.99 + 11,607.59 总提款：1,641,617.49 | QU5: PH09-2 | QV5: 2 | QW5: 5867 | QX5: 2582 | QY5: 1119036 | QZ5: 3407 | RA5: 5571451 | RB5: 5219226 | RC5: =RB5-RE5 -> 5047996 | RD5: =RA5-RB5 -> 352225 | RE5: 171230 | RF5: 218489.14 | RG5: =RA5*3.5% -> 195000.79 | RH5: =RF5*10% -> 21848.914 | RI5: =QV5*3306*31 -> 204972 | RJ5: =RD5-RG5-RH5 -> 135375.3 | RK5: =RA5/QZ5 -> 1635.2953 | RL5: =QY5/(RE5+RG5+RH5+RI5) -> 1.8869114 | RM5: =RD5/(RG5+RH5) -> 1.6242817 | RQ5: PH09-2 | RR5: 2 | RS5: 8051 | RT5: 3610 | RU5: 1119036 | RV5: 4382 | RW5: 3661277 | RX5: 3481353 | RY5: =RW5-RX5 -> 179924 | RZ5: 261770 | SA5: 0 | SB5: 7764.48 | SC5: =RW5*3.5% -> 128144.7 | SD5: =SB5*10% -> 776.448 | SE5: =RR5*3306*30 -> 198360 | SF5: =RY5-SC5-SD5-SE5 -> -147357.14 | SG5: =RW5/RV5 -> 835.52647 | SH5: =RU5/(RZ5+SC5+SD5+SE5) -> 1.8997264 | SI5: =RY5/(SC5+SD5+SE5) -> 0.54975364 | SM5: PH09-2 | SN5: 5 | SO5: 9472 | SP5: 3162 | SQ5: 1352512 | SR5: 3892 | SS5: 2121794.5 | ST5: 2039753 | SU5: =SS5-ST5 -> 82041.46 | SV5: 223470 | SW5: 0 | SX5: -32292.7 | SY5: =SS5*3.5% -> 74262.806 | SZ5: 0 | TA5: =SN5*4000*31 -> 620000 | TB5: =SU5-SY5-SZ5-TA5 -> -612221.35 | TC5: =SS5/SR5 -> 545.16816 | TD5: =SQ5/(SV5+SY5+SZ5+TA5) -> 1.4737536 | TE5: =SU5/(SY5+SZ5+TA5) -> 0.11817061 | TH5: PH09-2 | TI5: 6 | TJ5: 13676 | TK5: 5603 | TL5: 2166197.1 | TM5: 6086 | TN5: 2643162.4 | TO5: 2997447 | TP5: =TN5-TO5 -> -354284.6 | TQ5: 563590 | TR5: 0 | TS5: -364961.34 | TT5: =TN5*4% -> 105726.5 | TU5: 0 | TV5: =TI5*4000*28 -> 672000 | TW5: =TP5-TT5-TU5-TV5 -> -1132011.1 | TX5: =TN5/TM5 -> 434.30207 | TY5: =TL5/(TQ5+TT5+TU5+TV5) -> 1.6149784 | TZ5: =TP5/(TT5+TU5+TV5) -> -0.45553881 | UD5: PH09-2 | UE5: 4 | UF5: 7872 | UG5: 2386 | UH5: 921287 | UI5: 2386 | UJ5: 921287 | UK5: 916839 | UL5: =UJ5-UK5 -> 4448 | UM5: 148720 | UN5: 0 | UO5: -76572.68 | UP5: =UJ5*4% -> 36851.48 | UQ5: 0 | UR5: =UE5*4000*21 -> 336000 | US5: =UL5-UP5-UQ5-UR5 -> -368403.48 | UT5: =UJ5/UI5 -> 386.12196 | UU5: =UH5/(UM5+UP5+UQ5+UR5) -> 1.7663677 | UV5: =UL5/(UP5+UQ5+UR5) -> 0.011929683 | UW5: 1月11-31 | UZ5: PH09-2 | VH5: =VF5-VG5 -> 0 | VL5: =VF5*4% -> 0 | VM5: 0 | VN5: =VA5*4000*0 -> 0 | VO5: =VH5-VL5-VM5-VN5 -> 0 | VP5: =VF5/VE5 -> #DIV/0! | VQ5: =VD5/(VI5+VL5+VM5+VN5) -> #DIV/0! | VR5: =VH5/(VL5+VM5+VN5) -> #DIV/0! | VS5: 未开始
C6: PH25 | D6: 2 | E6: 4 | F6: ='PH25'!AJ4 -> 37 | G6: =(I6/F6)/S1 -> 2.6320166 | H6: ='PH25'!G4 -> 5130 | I6: ='PH25'!H4 -> 2532 | J6: ='PH25'!T4 -> 395999 | K6: ='PH25'!U4 -> 571810 | L6: ='PH25'!V4 -> 367848.8 | M6: =123553+1104499 -> 1228052 | N6: =88851+794379.8 -> 883230.8 | O6: =M6-N6 -> 344821.2 | P6: ='PH25'!J4 -> 2220 | Q6: ='PH25'!R4 -> 493879 | R6: ='PH25'!S4 -> 312594.8 | S6: ='PH25'!K4 -> 9423 | T6: =S6-I6 -> 6891 | U6: ='PH25'!W4 -> 4127611 | V6: ='PH25'!X4 -> 3335808.5 | W6: =U6-V6 -> 791802.51 | X6: ='PH25'!D4 -> 456003 | Y6: =326770.39+338089.67 -> 664860.06 | Z6: =U6*3.5% -> 144466.39 | AA6: =IF(Y6>0,Y6*20%,0) -> 132972.01 | AB6: =(D6*3200)*S1 -> 166400 | AC6: =(E6*1733)*S1 -> 180232 | AD6: =W6-Z6-AA6-X6-AB6-AC6 -> -288270.89 | AE6: =K6/I6 -> 225.83333 | AF6: =U6/S6 -> 438.03576 | AG6: =M6/(Z6+AA6+X6+AB6+AC6) -> 1.1370079 | AH6: =W6/(Z6+AA6+X6+AB6+AC6) -> 0.73310065 | AJ6: PH25 | AK6: 1 | AL6: 4 | AM6: 47 | AN6: =(AP6/AM6)/AZ1 -> 2.2120567 | AO6: 6705 | AP6: 3119 | AQ6: 453158 | AR6: 645933 | AS6: 387840.71 | AT6: 1333826 | AU6: 1086636.9 | AV6: =AT6-AU6 -> 247189.06 | AW6: 587951 | AX6: 587951 | AY6: 332130.75 | AZ6: 10789 | BA6: 7670 | BB6: 4735492 | BC6: 3777767.9 | BD6: =BB6-BC6 -> 957724.06 | BE6: 583747 | BF6: 830927.38 | BG6: =BB6*3.5% -> 165742.22 | BH6: =IF(BF6>0,BF6*20%,0) -> 166185.48 | BI6: =(AK6*3200)*AZ1 -> 96000 | BJ6: =(AL6*1733)*AZ1 -> 207960 | BK6: =BD6-BG6-BH6-BE6-BI6-BJ6 -> -261910.64 | BL6: =AR6/AP6 -> 207.09618 | BM6: =BB6/AZ6 -> 438.91853 | BN6: =AT6/(BG6+BH6+BE6+BI6) -> 1.3184337 | BO6: =BD6/(BG6+BH6+BE6+BI6+BJ6) -> 0.78525485 | BQ6: PH25 | BR6: 1 | BS6: 4 | BT6: 106 | BU6: 0.6923311 | BV6: 4632 | BW6: 2275 | BX6: 347172 | BY6: 486170 | BZ6: 267943.25 | CA6: 1217065 | CB6: 851211.25 | CC6: 365853.75 | CD6: 2007 | CE6: 424959 | CF6: 224939.25 | CG6: 9765 | CH6: 7490 | CI6: 5128130 | CJ6: 3883989 | CK6: =CI6-CJ6 -> 1244141 | CL6: 185570 | CM6: 1029091.4 | CN6: =CI6*3.5% -> 179484.55 | CO6: =IF(CM6>0,CM6*20%,0) -> 205818.29 | CP6: =(BR6*3200)*CI1 -> 99200 | CQ6: =(BS6*1733)*CI1 -> 214892 | CR6: =CK6-CN6-CO6-CL6-CP6-CQ6 -> 359176.16 | CS6: =BY6/BW6 -> 213.7011 | CT6: =CI6/CG6 -> 525.15412 | CU6: =CA6/(CN6+CO6+CL6+CP6) -> 1.8163175 | CV6: =CK6/(CN6+CO6+CL6+CP6+CQ6) -> 1.4058649 | CX6: PH25 | CY6: 0 | CZ6: 4 | DA6: 44 | DB6: 1.1575758 | DC6: 2984 | DD6: 1528 | DE6: 242580 | DF6: 329527 | DG6: 150434 | DH6: 765361 | DI6: 605872.07 | DJ6: =DH6-DI6 -> 159488.93 | DK6: 1297 | DL6: 273650 | DM6: 118785 | DN6: 9321 | DO6: 7793 | DP6: 4943536 | DQ6: 4132905 | DR6: =DP6-DQ6 -> 810631 | DS6: 242440 | DT6: 675976.49 | DU6: =DP6*3.5% -> 173023.76 | DV6: =IF(DT6>0,DT6*20%,0) -> 135195.3 | DW6: =(CY6*3200)*DP1 -> 0 | DX6: =(CZ6*1733)*DP1 -> 207960 | DY6: =DR6-DU6-DV6-DS6-DW6-DX6 -> 52011.942 | DZ6: =DF6/DD6 -> 215.65903 | EA6: =DP6/DN6 -> 530.36541 | EB6: =DH6/(DU6+DV6+DS6+DW6) -> 1.3899 | EC6: =DR6/(DU6+DV6+DS6+DW6+DX6) -> 1.0685613 | EE6: PH25 | EF6: 0 | EG6: 4 | EH6: 111 | EI6: 1.0340017 | EJ6: 6931 | EK6: 3558 | EL6: 555272 | EM6: 811949 | EN6: 461373.36 | EO6: 2026992 | EP6: 1742704.3 | EQ6: 284287.71 | ER6: 3083 | ES6: 712507 | ET6: 401116.76 | EU6: 14949 | EV6: 11391 | EW6: 6199233 | EX6: 5234837 | EY6: 964396 | EZ6: 486740 | FA6: 755538.81 | FB6: 216973.15 | FC6: 151107.76 | FD6: =(EF6*3200)*EW1 -> 0 | FE6: =(EG6*1733)*EW1 -> 214892 | FF6: -122646.92 | FG6: 228.20377 | FH6: 414.69215 | FI6: 2.3712475 | FJ6: 0.8871738 | FN6: PH25 | FO6: 0 | FP6: 5 | FQ6: 134 | FR6: =(FT6/FQ6)/GF1 -> 1.0013326 | FS6: 7766 | FT6: 3757 | FU6: 634256 | FV6: 909212 | FW6: 551697.2 | FX6: 2370398 | FY6: 1919135.2 | FZ6: =FX6-FY6 -> 451262.8 | GA6: 3212 | GB6: 771945 | GC6: 468516.2 | GD6: 14130 | GE6: 10373 | GF6: 6007821 | GG6: 5086933 | GH6: 920888 | GI6: 402970 | GJ6: 694386.66 | GK6: 210273.73 | GL6: 138877.33 | GM6: =(FO6*3200)*GF1 -> 0 | GN6: =(FP6*1733)*GF1 -> 242620 | GO6: -73853.067 | GP6: 242.00479 | GQ6: 425.18195 | GR6: =FX6/(GK6+GL6+GI6+GM6) -> 3.1516176 | GS6: =GH6/(GK6+GL6+GI6+GM6+GN6) -> 0.92575649 | GV6: PH25 | GW6: 1 | GX6: 4 | GY6: 110 | GZ6: =(HB6/GY6)/HL1 -> 0.84780059 | HA6: 6316 | HB6: 2891 | HC6: 460409 | HD6: 661223 | HE6: 421698 | HF6: 1595349 | HG6: 1270410 | HH6: =HF6-HG6 -> 324939 | HI6: 2439 | HJ6: 558544 | HK6: 346814 | HL6: 13540 | HM6: 10649 | HN6: 5612292 | HO6: 4683256 | HP6: 929036 | HQ6: 325250 | HR6: 763210.47 | HS6: 196430.22 | HT6: 53058.224 | HU6: =(GW6*3200)*31 -> 99200 | HV6: =(GX6*1733)*31 -> 214892 | HW6: 23682.556 | HX6: 228.71774 | HY6: 414.49719 | HZ6: =HF6/(HS6+HT6+HQ6+HU6) -> 2.3672028 | IA6: =HP6/(HS6+HT6+HQ6+HU6+HV6) -> 1.0452342 | ID6: PH25 | IE6: 5 | IF6: 0 | IG6: 104 | IH6: =(IJ6/IG6)/IT1 -> 1.0970844 | II6: 7609 | IJ6: 3537 | IK6: 540964.95 | IL6: 849098.95 | IM6: 533234 | IN6: 2451843.9 | IO6: 1859254 | IP6: =IN6-IO6 -> 592589.89 | IQ6: 3015 | IR6: 722404.99 | IS6: 406182 | IT6: 16869 | IU6: 13332 | IV6: 6927873.5 | IW6: 5478456 | IX6: =IV6-IW6 -> 1449417.5 | IY6: 368840 | IZ6: 1198363.1 | JA6: =IV6*3.5% -> 242475.57 | JB6: =IZ6*20% -> 239672.62 | JC6: 214892 | JD6: 0 | JE6: =IX6-JA6-JB6-IY6-JC6 -> 383537.32 | JF6: =IL6/IJ6 -> 240.0619 | JG6: =IV6/IT6 -> 410.68667 | JH6: =IL6/(JA6+JB6+IY6+JC6) -> 0.79661763 | JI6: =IX6/(JA6+JB6+IY6+JC6) -> 1.3598316 | JL6: PH25 | JM6: 5 | JN6: 0 | JO6: 145 | JP6: =(JR6/JO6)/KB1 -> 0.72551724 | JQ6: 7112 | JR6: 3156 | JS6: 461749 | JT6: 685804 | JU6: 460636 | JV6: 1732351 | JW6: 1392244 | JX6: =JV6-JW6 -> 340107 | JY6: 2711 | JZ6: 594570 | KA6: 386307 | KB6: 14859 | KC6: 11703 | KD6: 5692022 | KE6: 4766810 | KF6: =KD6-KE6 -> 925212 | KG6: 229600 | KH6: 676202.99 | KI6: =KD6*3.5% -> 199220.77 | KJ6: =KH6*20% -> 135240.6 | KK6: 246086 | KL6: 0 | KM6: =KF6-KI6-KJ6-KG6-KK6 -> 115064.63 | KN6: =JT6/JR6 -> 217.30165 | KO6: =KD6/KB6 -> 383.06898 | KP6: =JT6/(KI6+KJ6+KG6+KK6) -> 0.84651759 | KQ6: =KF6/(KI6+KJ6+KG6+KK6) -> 1.1420293 | KT6: PH25 | KU6: 5 | KV6: 0 | KW6: 155 | KX6: =(KZ6/KW6)/LJ1 -> 0.89469303 | KY6: 11017 | KZ6: 4299 | LA6: 607818 | LB6: 901094 | LC6: 649885.48 | LD6: 2488573 | LE6: 2179589.5 | LF6: =LE6 -> 2179589.5 | LG6: 3542 | LH6: 746219 | LI6: 492562.48 | LJ6: 20676 | LK6: 16377 | LL6: 7535790 | LM6: 6726566 | LN6: 809224 | LO6: 294730 | LP6: 382300.48 | LQ6: 263752.65 | LR6: 76460.096 | LS6: 254751 | LT6: 0 | LU6: -80469.746 | LV6: 209.60549 | LW6: 364.4704 | LX6: 1.0128137 | LY6: 0.90955343 | MB6: PH25 | MC6: 5 | MD6: 0 | ME6: 131 | MF6: =(MH6/ME6)/MR1 -> 1.540458 | MG6: 13408 | MH6: 6054 | MI6: 873944 | MJ6: 1257282 | MK6: 869933 | ML6: 3730819 | MM6: 2872836 | MN6: =ML6-MM6 -> 857983 | MO6: 5044 | MP6: 1045272 | MQ6: 729309 | MR6: 22982 | MS6: 16928 | MT6: 7954185 | MU6: 6396257 | MV6: =MT6-MU6 -> 1557928 | MW6: 447520 | MX6: 1233347.1 | MY6: =MT6*3.5% -> 278396.47 | MZ6: =MX6*20% -> 246669.41 | NA6: 259950 | NB6: =MV6-MY6-MZ6-MW6-NA6 -> 325392.11 | NC6: 0 | ND6: =MJ6/MH6 -> 207.6779 | NE6: =MT6/MR6 -> 346.105 | NF6: =MJ6/(MY6+MZ6+MW6+NA6) -> 1.0200774 | NG6: =MV6/(MY6+MZ6+MW6+NA6) -> 1.2640021 | NJ6: PH25 | NK6: 5 | NL6: 0 | NM6: 123 | NN6: =(NP6/NM6)/NZ1 -> 1.9470233 | NO6: 13747 | NP6: 7424 | NQ6: 1051397 | NR6: 1494151 | NS6: 889205 | NT6: 4337990 | NU6: 3520123 | NV6: =NT6-NU6 -> 817867 | NW6: 6084 | NX6: 1232526 | NY6: 716620 | NZ6: 24614 | OA6: =NZ6-NP6 -> 17190 | OB6: 7765222 | OC6: 6249417 | OD6: =OB6-OC6 -> 1515805 | OE6: 580460 | OF6: 1132100.3 | OG6: =OB6*3.5% -> 271782.77 | OH6: =OF6*20% -> 226420.07 | OI6: 202761 | OJ6: 0 | OK6: =OD6-OG6-OH6-OE6-OI6 -> 234381.16 | OL6: =NR6/NP6 -> 201.25956 | OM6: =OB6/NZ6 -> 315.47989 | ON6: =NR6/(OG6+OH6+OE6+OI6) -> 1.1660084 | OO6: =OD6/(OG6+OH6+OE6+OI6) -> 1.1829068 | OS6: PH25 | OT6: 5 | OU6: 93 | OV6: 17608 | OW6: 8174 | OX6: 1137991 | OY6: 1579435 | OZ6: 1082183 | PA6: 4162836 | PB6: 3914757 | PC6: 20460 | PD6: 12286 | PE6: 6338672 | PF6: 5888646 | PG6: =PE6-PF6 -> 450026 | PH6: 703870 | PI6: 94517.98 | PJ6: =PE6*3.5% -> 221853.52 | PK6: =PI6*20% -> 18903.596 | PL6: =OT6*1733*PF1+1 -> 268616 | PM6: =PG6-PJ6-PK6-PH6-PL6 -> -763217.12 | PN6: =OY6/OW6 -> 193.22669 | PO6: =PE6/PC6 -> 309.80802 | PP6: =OY6/(PH6+PJ6+PK6+PL6) -> 1.3018289 | PQ6: =PG6/(PJ6+PK6+PH6+PL6) -> 0.37092813 | PU6: PH25 | PV6: 5 | PW6: 74 | PX6: 5002 | PY6: 2154 | PZ6: 325352 | QA6: 433141 | QB6: 243203 | QC6: 7320 | QD6: 5166 | QE6: 2672222 | QF6: 2353291 | QG6: 318931 | QH6: 100050 | QI6: 195643.63 | QJ6: =QE6*3.5% -> 93527.77 | QK6: =QI6*20% -> 39128.726 | QL6: =PV6*3306*QG1+1 -> 495901 | QM6: =QG6-QJ6-QK6 -> 186274.5 | QN6: =PZ6/PY6 -> 151.0455 | QO6: =QE6/QC6 -> 365.05765 | QP6: =QA6/(QH6+QJ6+QK6+QL6) -> 0.59447783 | QQ6: =QG6/(QJ6+QK6) -> 2.4041868 | QR6: 披索 | QT6: 5-18玩家提款：10,236.73/ 5-23玩家提款：21,365.99/ 5-27玩家提款：20,993.34 总提款：52,596.06 | QU6: PH25 | QV6: 3 | QW6: 9095 | QX6: 2690 | QY6: 1436957 | QZ6: 3741 | RA6: 3457151 | RB6: 2777362 | RC6: =RB6-RE6 -> 2619292 | RD6: =RA6-RB6 -> 679789 | RE6: 158070 | RF6: 567308.18 | RG6: =RA6*3.5% -> 121000.29 | RH6: =RF6*10% -> 56730.818 | RI6: =QV6*3306*31 -> 307458 | RJ6: =RD6-RG6-RH6 -> 502057.9 | RK6: =RA6/QZ6 -> 924.12483 | RL6: =QY6/(RE6+RG6+RH6+RI6) -> 2.2338697 | RM6: =RD6/(RG6+RH6) -> 3.8248173 | RQ6: PH25 | RR6: 3 | RS6: 9571 | RT6: 2972 | RU6: 1483546 | RV6: 3976 | RW6: 3698674 | RX6: 3965456 | RY6: =RW6-RX6 -> -266782.01 | RZ6: 172230 | SA6: 0 | SB6: -427399.82 | SC6: =RW6*3.5% -> 129453.59 | SD6: 0 | SE6: =RR6*3306*30 -> 297540 | SF6: =RY6-SC6-SD6-SE6 -> -693775.6 | SG6: =RW6/RV6 -> 930.25 | SH6: =RU6/(RZ6+SC6+SD6+SE6) -> 2.4757804 | SI6: =RY6/(SC6+SD6+SE6) -> -0.6247916 | SM6: PH25 | SN6: 4 | SO6: 9342 | SP6: 2508 | SQ6: 1513168 | SR6: 3575 | SS6: 3212716.2 | ST6: 3233549 | SU6: =SS6-ST6 -> -20832.83 | SV6: 171630 | SW6: 0 | SX6: -138896.98 | SY6: =SS6*3.5% -> 112445.07 | SZ6: 0 | TA6: =SN6*4000*31 -> 496000 | TB6: =SU6-SY6-SZ6-TA6 -> -629277.9 | TC6: =SS6/SR6 -> 898.66187 | TD6: =SQ6/(SV6+SY6+SZ6+TA6) -> 1.9397723 | TE6: =SU6/(SY6+SZ6+TA6) -> -0.034239459 | TH6: PH25 | TI6: 4 | TJ6: 12618 | TK6: 4504 | TL6: 2135920 | TM6: 5483 | TN6: 3312495.9 | TO6: 3299113 | TP6: =TN6-TO6 -> 13382.89 | TQ6: 490980 | TR6: 0 | TS6: -133796.78 | TT6: =TN6*4% -> 132499.84 | TU6: 0 | TV6: =TI6*4000*28 -> 448000 | TW6: =TP6-TT6-TU6-TV6 -> -567116.95 | TX6: =TN6/TM6 -> 604.13932 | TY6: =TL6/(TQ6+TT6+TU6+TV6) -> 1.9934299 | TZ6: =TP6/(TT6+TU6+TV6) -> 0.023054081 | UD6: PH25 | UE6: 4 | UF6: 12769 | UG6: 5071 | UH6: 2872205.2 | UI6: 5126 | UJ6: 3012780.2 | UK6: 3259643 | UL6: =UJ6-UK6 -> -246862.76 | UM6: 310385 | UN6: 0 | UO6: -349214.9 | UP6: =UJ6*4% -> 120511.21 | UQ6: 0 | UR6: =UE6*4000*31 -> 496000 | US6: =UL6-UP6-UQ6-UR6 -> -863373.97 | UT6: =UJ6/UI6 -> 587.74488 | UU6: =UH6/(UM6+UP6+UQ6+UR6) -> 3.0987345 | UV6: =UL6/(UP6+UQ6+UR6) -> -0.40041893 | UZ6: PH25 | VA6: 4 | VB6: 311 | VC6: 132 | VD6: 49133 | VE6: 132 | VF6: 49133 | VG6: 45506 | VH6: =VF6-VG6 -> 3627 | VI6: 0 | VJ6: 0 | VK6: -577.76 | VL6: =VF6*4% -> 1965.32 | VM6: 0 | VN6: =VA6*4000*7 -> 112000 | VO6: =VH6-VL6-VM6-VN6 -> -110338.32 | VP6: =VF6/VE6 -> 372.2197 | VQ6: =VD6/(VI6+VL6+VM6+VN6) -> 0.43112238 | VR6: =VH6/(VL6+VM6+VN6) -> 0.031825471 | VS6: 12月25-31
C7: PH18 | D7: 3 | E7: 2 | F7: ='PH18'!AJ4 -> 37 | G7: =(I7/F7)/S1 -> 2.3534304 | H7: ='PH18'!G4 -> 4374 | I7: ='PH18'!H4 -> 2264 | J7: ='PH18'!T4 -> 351982 | K7: ='PH18'!U4 -> 489755 | L7: ='PH18'!V4 -> 405034.16 | M7: =178185+1151565 -> 1329750 | N7: =165390.3+1217405.32 -> 1382795.6 | O7: =M7-N7 -> -53045.62 | P7: ='PH18'!J4 -> 2034 | Q7: ='PH18'!R4 -> 396018 | R7: ='PH18'!S4 -> 262496 | S7: ='PH18'!K4 -> 8992 | T7: =S7-I7 -> 6728 | U7: ='PH18'!W4 -> 4557690.5 | V7: ='PH18'!X4 -> 4055648.6 | W7: =U7-V7 -> 502041.92 | X7: ='PH18'!D4 -> 331462 | Y7: =252642.65+114204.64 -> 366847.29 | Z7: =U7*3.5% -> 159519.17 | AA7: =IF(Y7>0,Y7*20%,0) -> 73369.458 | AB7: =(D7*3200)*S1 -> 249600 | AC7: =(E7*1733)*S1 -> 90116 | AD7: =W7-Z7-AA7-X7-AB7-AC7 -> -402024.71 | AE7: =K7/I7 -> 216.32288 | AF7: =U7/S7 -> 506.8606 | AG7: =M7/(Z7+AA7+X7+AB7+AC7) -> 1.470854 | AH7: =W7/(Z7+AA7+X7+AB7+AC7) -> 0.55531518 | AJ7: PH18 | AK7: 3 | AL7: 2 | AM7: 29 | AN7: =(AP7/AM7)/AZ1 -> 2.583908 | AO7: 3825 | AP7: 2248 | AQ7: 386665 | AR7: 1101256 | AS7: 312535.11 | AT7: 1923477.5 | AU7: 1267336.1 | AV7: =AT7-AU7 -> 656141.35 | AW7: 1062648 | AX7: 1062648 | AY7: 285088.11 | AZ7: 9211 | BA7: 6963 | BB7: 5873504.5 | BC7: 4026910.5 | BD7: =BB7-BC7 -> 1846594.1 | BE7: 305170 | BF7: 1827228.4 | BG7: =BB7*3.5% -> 205572.66 | BH7: =IF(BF7>0,BF7*20%,0) -> 365445.69 | BI7: =(AK7*3200)*AZ1 -> 288000 | BJ7: =(AL7*1733)*AZ1 -> 103980 | BK7: =BD7-BG7-BH7-BE7-BI7-BJ7 -> 578425.71 | BL7: =AR7/AP7 -> 489.88256 | BM7: =BB7/AZ7 -> 637.66198 | BN7: =AT7/(BG7+BH7+BE7+BI7) -> 1.6522047 | BO7: =BD7/(BG7+BH7+BE7+BI7+BJ7) -> 1.4561111 | BQ7: PH18 | BR7: 2 | BS7: 1 | BT7: 48 | BU7: 0.7936828 | BV7: 1938 | BW7: 1181 | BX7: 177747.4 | BY7: 262660 | BZ7: 152117 | CA7: 612944.4 | CB7: 525546 | CC7: 87398.4 | CD7: 1028 | CE7: 224524 | CF7: 132647 | CG7: 9246 | CH7: 8065 | CI7: 7210798 | CJ7: 5158838 | CK7: =CI7-CJ7 -> 2051960 | CL7: 167640 | CM7: 1787157.4 | CN7: =CI7*3.5% -> 252377.93 | CO7: =IF(CM7>0,CM7*20%,0) -> 357431.48 | CP7: =(BR7*3200)*CI1 -> 198400 | CQ7: =(BS7*1733)*CI1 -> 53723 | CR7: =CK7-CN7-CO7-CL7-CP7-CQ7 -> 1022387.6 | CS7: =BY7/BW7 -> 222.40474 | CT7: =CI7/CG7 -> 779.88298 | CU7: =CA7/(CN7+CO7+CL7+CP7) -> 0.62811371 | CV7: =CK7/(CN7+CO7+CL7+CP7+CQ7) -> 1.9930216 | CX7: PH18 | CY7: 2 | CZ7: 1 | DA7: 36 | DB7: 1.2916667 | DC7: 2361 | DD7: 1395 | DE7: 212835 | DF7: 291643 | DG7: 168420.4 | DH7: 1009913.8 | DI7: 830178.17 | DJ7: =DH7-DI7 -> 179735.66 | DK7: 1245 | DL7: 260759 | DM7: 144634.9 | DN7: 10172 | DO7: 8777 | DP7: 7516135.3 | DQ7: 6694214 | DR7: =DP7-DQ7 -> 821921.28 | DS7: 235810 | DT7: 582806.6 | DU7: =DP7*3.5% -> 263064.73 | DV7: =IF(DT7>0,DT7*20%,0) -> 116561.32 | DW7: =(CY7*3200)*DP1 -> 192000 | DX7: =(CZ7*1733)*DP1 -> 51990 | DY7: =DR7-DU7-DV7-DS7-DW7-DX7 -> -37504.775 | DZ7: =DF7/DD7 -> 209.06308 | EA7: =DP7/DN7 -> 738.90437 | EB7: =DH7/(DU7+DV7+DS7+DW7) -> 1.2507663 | EC7: =DR7/(DU7+DV7+DS7+DW7+DX7) -> 0.95636067 | EE7: PH18 | EF7: 2 | EG7: 1 | EH7: 40 | EI7: 1.9846774 | EJ7: 4811 | EK7: 2461 | EL7: 393279.41 | EM7: 532568.41 | EN7: 323728.38 | EO7: 1350562.4 | EP7: 1180889.4 | EQ7: 169673.05 | ER7: 2092 | ES7: 441874.41 | ET7: 264490.38 | EU7: 14566 | EV7: 12105 | EW7: 8250113.8 | EX7: 7568715 | EY7: 681398.78 | EZ7: 315490 | FA7: 427940.13 | FB7: 288753.98 | FC7: 85588.026 | FD7: =(EF7*3200)*EW1 -> 198400 | FE7: =(EG7*1733)*EW1 -> 53723 | FF7: -293602.23 | FG7: 216.40325 | FH7: 566.39529 | FI7: 1.4659662 | FJ7: 0.69886982 | FN7: PH18 | FO7: 2 | FP7: 1 | FQ7: 62 | FR7: =(FT7/FQ7)/GF1 -> 1.2713134 | FS7: 4966 | FT7: 2207 | FU7: 373153.07 | FV7: 521188.07 | FW7: 344679 | FX7: 1768725.3 | FY7: 1658044 | FZ7: =FX7-FY7 -> 110681.27 | GA7: 1864 | GB7: 427415.07 | GC7: 273927 | GD7: 14175 | GE7: 11968 | GF7: 7700878.3 | GG7: 6703863.2 | GH7: 997015.03 | GI7: 285630 | GJ7: 715176.18 | GK7: 269530.74 | GL7: 143035.24 | GM7: =(FO7*3200)*GF1 -> 179200 | GN7: =(FP7*1733)*GF1 -> 48524 | GO7: 41247.054 | GP7: 236.15227 | GQ7: 543.27184 | GR7: =FX7/(GK7+GL7+GI7+GM7) -> 2.0158803 | GS7: =GH7/(GK7+GL7+GI7+GM7+GN7) -> 1.0767832 | GV7: PH18 | GW7: 2 | GX7: 1 | GY7: 50 | GZ7: =(HB7/GY7)/HL1 -> 1.883871 | HA7: 7039 | HB7: 2920 | HC7: 444871 | HD7: 607365 | HE7: 419779 | HF7: 1616410.1 | HG7: 1511247 | HH7: =HF7-HG7 -> 105163.06 | HI7: 2448 | HJ7: 506301 | HK7: 360356 | HL7: 18094 | HM7: 15174 | HN7: 8551758.3 | HO7: 7699218 | HP7: 852540.26 | HQ7: 415560 | HR7: 531792.83 | HS7: 299311.54 | HT7: 69371.85 | HU7: =(GW7*3200)*31 -> 198400 | HV7: =(GX7*1733)*31 -> 53723 | HW7: -216872.13 | HX7: 208.00171 | HY7: 472.6295 | HZ7: =HF7/(HS7+HT7+HQ7+HU7) -> 1.644961 | IA7: =HP7/(HS7+HT7+HQ7+HU7+HV7) -> 0.82262438 | ID7: PH18 | IE7: 3 | IF7: 0 | IG7: 58 | IH7: =(IJ7/IG7)/IT1 -> 3.057842 | II7: 13675 | IJ7: 5498 | IK7: 816908 | IL7: 1173968.9 | IM7: 735381 | IN7: 3215200.5 | IO7: 2943729 | IP7: =IN7-IO7 -> 271471.5 | IQ7: 4565 | IR7: 993658.89 | IS7: 603710 | IT7: 26333 | IU7: 20835 | IV7: 11702604 | IW7: 9537748 | IX7: =IV7-IW7 -> 2164855.6 | IY7: 500700 | IZ7: 1697468.3 | JA7: =IV7*3.5% -> 409591.13 | JB7: =IZ7*20% -> 339493.67 | JC7: 221824 | JD7: 0 | JE7: =IX7-JA7-JB7-IY7-JC7 -> 693246.84 | JF7: =IL7/IJ7 -> 213.52654 | JG7: =IV7/IT7 -> 444.40829 | JH7: =IL7/(JA7+JB7+IY7+JC7) -> 0.79774523 | JI7: =IX7/(JA7+JB7+IY7+JC7) -> 1.4710809 | JL7: PH18 | JM7: 5 | JN7: 0 | JO7: 88 | JP7: =(JR7/JO7)/KB1 -> 1.5155303 | JQ7: 8925 | JR7: 4001 | JS7: 586063 | JT7: 833665 | JU7: 454778 | JV7: 2076869.8 | JW7: 1667987 | JX7: =JV7-JW7 -> 408882.82 | JY7: 3316 | JZ7: 687740 | KA7: 366665 | KB7: 22103 | KC7: 18102 | KD7: 10406089 | KE7: 8457605 | KF7: =KD7-KE7 -> 1948483.8 | KG7: 379360 | KH7: 1578733.6 | KI7: =KD7*3.5% -> 364213.11 | KJ7: =KH7*20% -> 315746.71 | KK7: 259950 | KL7: 0 | KM7: =KF7-KI7-KJ7-KG7-KK7 -> 629213.95 | KN7: =JT7/JR7 -> 208.36416 | KO7: =KD7/KB7 -> 470.79984 | KP7: =JT7/(KI7+KJ7+KG7+KK7) -> 0.63191395 | KQ7: =KF7/(KI7+KJ7+KG7+KK7) -> 1.4769411 | KT7: PH18 | KU7: 5 | KV7: 0 | KW7: 125 | KX7: =(KZ7/KW7)/LJ1 -> 1.4309677 | KY7: 13728 | KZ7: 5545 | LA7: 841950 | LB7: 1279811 | LC7: 811336 | LD7: 4175580.7 | LE7: 3529556 | LF7: =LE7 -> 3529556 | LG7: 4640 | LH7: 1038759 | LI7: 650982 | LJ7: 27158 | LK7: 21613 | LL7: 11362924 | LM7: 9899067 | LN7: 1463856.6 | LO7: 344550 | LP7: 1013835.5 | LQ7: 397702.33 | LR7: 202767.1 | LS7: 268615 | LT7: 0 | LU7: 250222.19 | LV7: 230.80451 | LW7: 418.4006 | LX7: 1.0545276 | LY7: 1.2061759 | MB7: PH18 | MC7: 5 | MD7: 0 | ME7: 142 | MF7: =(MH7/ME7)/MR1 -> 1.5600939 | MG7: 14928 | MH7: 6646 | MI7: 1089920.4 | MJ7: 1740947 | MK7: 1093491 | ML7: 4894921.1 | MM7: 4218503 | MN7: =ML7-MM7 -> 676418.1 | MO7: 5574 | MP7: 1474642.4 | MQ7: 729309 | MR7: 27821 | MS7: 21175 | MT7: 16118826 | MU7: 15815437 | MV7: =MT7-MU7 -> 303388.75 | MW7: 503340 | MX7: -258291.46 | MY7: =MT7*3.5% -> 564158.9 | MZ7: 0 | NA7: 259950 | NB7: =MV7-MY7-MZ7-MW7-NA7 -> -1024060.2 | NC7: 0 | ND7: =MJ7/MH7 -> 261.95411 | NE7: =MT7/MR7 -> 579.37622 | NF7: =MJ7/(MY7+MZ7+MW7+NA7) -> 1.3114983 | NG7: =MV7/(MY7+MZ7+MW7+NA7) -> 0.22855023 | NJ7: PH18 | NK7: 7 | NL7: 0 | NM7: 145 | NN7: =(NP7/NM7)/NZ1 -> 2.2157953 | NO7: 18131 | NP7: 9960 | NQ7: 1429557 | NR7: 1999654 | NS7: 1448096 | NT7: 5004447.7 | NU7: 4615209 | NV7: =NT7-NU7 -> 389238.66 | NW7: 8477 | NX7: 1678195 | NY7: 1211360 | NZ7: 30033 | OA7: =NZ7-NP7 -> 20073 | OB7: 10161098 | OC7: 9583644 | OD7: =OB7-OC7 -> 577454.14 | OE7: 936840 | OF7: 71129.53 | OG7: =OB7*3.5% -> 355638.43 | OH7: =OF7*20% -> 14225.906 | OI7: 344867 | OJ7: 0 | OK7: =OD7-OG7-OH7-OE7-OI7 -> -1074117.2 | OL7: =NR7/NP7 -> 200.76847 | OM7: =OB7/NZ7 -> 338.33111 | ON7: =NR7/(OG7+OH7+OE7+OI7) -> 1.2107585 | OO7: =OD7/(OG7+OH7+OE7+OI7) -> 0.34963923 | OS7: PH18 | OT7: 6 | OU7: 175 | OV7: 22136 | OW7: 11483 | OX7: 1676707 | OY7: 2217047 | OZ7: 1487147 | PA7: 5292446.8 | PB7: 4474229 | PC7: 29075 | PD7: 17592 | PE7: 8439571.8 | PF7: 6953178 | PG7: =PE7-PF7 -> 1486393.8 | PH7: 1153200 | PI7: 948017.1 | PJ7: =PE7*3.5% -> 295385.01 | PK7: =PI7*20% -> 189603.42 | PL7: =OT7*1733*PF1+1 -> 322339 | PM7: =PG7-PJ7-PK7-PH7-PL7 -> -474133.59 | PN7: =OY7/OW7 -> 193.07211 | PO7: =PE7/PC7 -> 290.26902 | PP7: =OY7/(PH7+PJ7+PK7+PL7) -> 1.1308421 | PQ7: =PG7/(PJ7+PK7+PH7+PL7) -> 0.75816018 | PU7: PH18 | PV7: 6 | PW7: 196 | PX7: 18694 | PY7: 8791 | PZ7: 1329954 | QA7: 1808204 | QB7: 1066383 | QC7: 22040 | QD7: 13249 | QE7: 7178463.8 | QF7: 6638412 | QG7: 540051.76 | QH7: 806690 | QI7: 167385.12 | QJ7: =QE7*3.5% -> 251246.23 | QK7: =QI7*20% -> 33477.024 | QL7: =PV7*3306*QG1+1 -> 595081 | QM7: =QG7-QJ7-QK7 -> 255328.5 | QN7: =PZ7/PY7 -> 151.28586 | QO7: =QE7/QC7 -> 325.70162 | QP7: =QA7/(QH7+QJ7+QK7+QL7) -> 1.0721673 | QQ7: =QG7/(QJ7+QK7) -> 1.8967603 | QR7: 披索 | QT7: 5-04玩家提款：40,637.04 / 5-08玩家提款：36,102.51/ 5-20玩家提款：30,655.35/ 5-26玩家提款：27,304.14/ 5-28玩家提款：18,587.40/ 5-29玩家提款：33,497.90/ 5-30玩家提款：60,132.61 总提款：246,916.95 | QU7: PH18 | QV7: 4 | QW7: 14715 | QX7: 7063 | QY7: 3205612.9 | QZ7: 8372 | RA7: 5662956.2 | RB7: 5146982 | RC7: =RB7-RE7 -> 4454182 | RD7: =RA7-RB7 -> 515974.24 | RE7: 692800 | RF7: 219056.76 | RG7: =RA7*3.5% -> 198203.47 | RH7: =RF7*10% -> 21905.676 | RI7: =QV7*3306*31 -> 409944 | RJ7: =RD7-RG7-RH7 -> 295865.1 | RK7: =RA7/QZ7 -> 676.41618 | RL7: =QY7/(RE7+RG7+RH7+RI7) -> 2.4232568 | RM7: =RD7/(RG7+RH7) -> 2.3441745 | RQ7: PH18 | RR7: 3 | RS7: 11178 | RT7: 5481 | RU7: 2359144.9 | RV7: 6333 | RW7: 3641576 | RX7: 3457365 | RY7: =RW7-RX7 -> 184211.01 | RZ7: 486240 | SA7: 0 | SB7: 37856.94 | SC7: =RW7*3.5% -> 127455.16 | SD7: =SB7*10% -> 3785.694 | SE7: =RR7*3306*30 -> 297540 | SF7: =RY7-SC7-SD7-SE7 -> -244569.84 | SG7: =RW7/RV7 -> 575.01595 | SH7: =RU7/(RZ7+SC7+SD7+SE7) -> 2.5782416 | SI7: =RY7/(SC7+SD7+SE7) -> 0.42961575 | SM7: PH18 | SN7: 3 | SO7: 8814 | SP7: 4190 | SQ7: 1657239.3 | SR7: 5421 | SS7: 3619162.3 | ST7: 3263071 | SU7: =SS7-ST7 -> 356091.27 | SV7: 482777 | SW7: 0 | SX7: 258937.49 | SY7: =SS7*3.5% -> 126670.68 | SZ7: =SX7*10% -> 25893.749 | TA7: =SN7*4000*31 -> 372000 | TB7: =SU7-SY7-SZ7-TA7 -> -168473.16 | TC7: =SS7/SR7 -> 667.61894 | TD7: =SQ7/(SV7+SY7+SZ7+TA7) -> 1.6451614 | TE7: =SU7/(SY7+SZ7+TA7) -> 0.67883229 | TH7: PH18 | TI7: 3 | TJ7: 17299 | TK7: 7593 | TL7: 2966813.4 | TM7: 8965 | TN7: 5070308.2 | TO7: 5226826 | TP7: =TN7-TO7 -> -156517.76 | TQ7: 1110570 | TR7: 0 | TS7: -248917.46 | TT7: =TN7*4% -> 202812.33 | TU7: 0 | TV7: =TI7*4000*28 -> 336000 | TW7: =TP7-TT7-TU7-TV7 -> -695330.09 | TX7: =TN7/TM7 -> 565.56701 | TY7: =TL7/(TQ7+TT7+TU7+TV7) -> 1.7987421 | TZ7: =TP7/(TT7+TU7+TV7) -> -0.2904866 | UD7: PH18 | UE7: 4 | UF7: 19200 | UG7: 9340 | UH7: 4190588 | UI7: 10028 | UJ7: 5715637 | UK7: 6556834 | UL7: =UJ7-UK7 -> -841197.01 | UM7: 906685 | UN7: 0 | UO7: -967693.71 | UP7: =UJ7*4% -> 228625.48 | UQ7: 0 | UR7: =UE7*4000*31 -> 496000 | US7: =UL7-UP7-UQ7-UR7 -> -1565822.5 | UT7: =UJ7/UI7 -> 569.96779 | UU7: =UH7/(UM7+UP7+UQ7+UR7) -> 2.5688476 | UV7: =UL7/(UP7+UQ7+UR7) -> -1.1608714 | UZ7: PH18 | VA7: 4 | VB7: 7796 | VC7: 4204 | VD7: 2123082 | VE7: 4204 | VF7: 2123082 | VG7: 2871507 | VH7: =VF7-VG7 -> -748425 | VI7: 259060 | VJ7: 0 | VK7: -822129.71 | VL7: =VF7*4% -> 84923.28 | VM7: 0 | VN7: =VA7*4000*20 -> 320000 | VO7: =VH7-VL7-VM7-VN7 -> -1153348.3 | VP7: =VF7/VE7 -> 505.01475 | VQ7: =VD7/(VI7+VL7+VM7+VN7) -> 3.1974932 | VR7: =VH7/(VL7+VM7+VN7) -> -1.8483131 | VS7: 12月12-31
